Workbook

Sheet 🏠 PORTADA
E2: 🌎 CALCULADORA PROFESIONAL DE COSTOS DE IMPORTACIÓN
E3: P E R Ú — S I S T E M A D E G E S T I Ó N A D U A N E R A
E6: La herramienta definitiva para calcular costos, tributos y precios de importación en el Perú
E8: ✦ ¿QUÉ INCLUYE ESTA HERRAMIENTA? ✦
E9: 📋 DATOS GENERALES | G9: Registro completo del DUA, importador, Incoterm y parámetros tributarios configurables
E10: 🧾 FACTURA COMERCIAL | G10: Ingreso de hasta 30+ productos con cálculo automático de FOB total y prorrateo unitario
E11: 📦 GASTOS DE IMPORTACIÓN | G11: 21 conceptos pre-cargados: handling, tracción, almacenaje, agente, transporte y más
E12: ⚖️ TRIBUTOS ADUANEROS | G12: Cálculo automático: CIF, ADV, IPM, IGV, Deuda Aduanera y Percepción según SUNAT
E13: 🧮 COSTOS POR PRODUCTO | G13: Factor de prorrateo (6 dígitos) y costo unitario en USD y S/. para cada producto
E14: 💰 PRECIO DE VENTA | G14: Margen global o por producto. VV = CT/(1-Margen%). Punto de equilibrio automático
E15: 🏦 CRÉDITO FISCAL | G15: Detalle completo: IGV, IPM, Percepción y gastos afectos. Valor total recuperable en S/.
E16: 📊 DASHBOARD EJECUTIVO | G16: 8+ gráficos dinámicos: costos, tributos, márgenes, rentabilidad por producto y más
E18: ✦ FLUJO DE TRABAJO — 8 PASOS SIMPLES ✦
E19: PASO 1 Configura | F19: PASO 2 Carga | G19: PASO 3 Registra | H19: PASO 4 Automático | I19: PASO 5 Analiza | J19: PASO 6 Define | K19: PASO 7 Recupera | L19: PASO 8 Decide
E20: Datos generales, tipo de cambio y parámetros tributarios | F20: Productos de la factura comercial con FOB unitario | G20: Gastos de importación pagados a operadores y agentes | H20: El sistema calcula CIF, tributos y deuda aduanera | I20: Revisa el costo unitario y factor de prorrateo | J20: Establece tu margen y obtén precios de venta sugeridos | K20: Visualiza tu crédito fiscal total a recuperar | L20: Revisa el dashboard con todos los KPIs y gráficos
E22: ✦ LEYENDA DE COLORES ✦
E23: 🟡 AMARILLO Campo editable — ingresa tus datos aquí | G23: 🟢 VERDE Calculado automáticamente — no editar | I23: 🔵 AZUL Total o resumen principal de la sección | K23: 🟠 NARANJA Precio de venta o margen de ganancia
E25: ⚠️ IMPORTANTE: Actualice el Tipo de Cambio antes de cada operación | Verifique el Ad Valorem con su Agente de Aduanas
E26: 📧 Herramienta desarrollada para uso profesional en comercio exterior peruano Elaborado por : Rosalinda Jiménez Espinoza By Sally Control Tower Con Derechos de Autoria | J26: Versión 2.0 | 2026

Sheet 📖 Instrucciones
A1: 📖 GUÍA COMPLETA DE USO — CALCULADORA DE COSTOS DE IMPORTACIÓN PERÚ
D3: PASO 1 — 📋 DATOS GENERALES
D4: → Complete todos los datos en color AMARILLO: DUA, razón social, RUC, fecha, país, proveedor, incoterm, canal. | F4: "📌 NOTA IMPORTANTE — USO DE LA PLANTILLA Esta calculadora está diseñada para ser usada por operación de importación. Si realizas varias importaciones, te recomendamos seguir este flujo de trabajo: 1️⃣ Completa esta plantilla con los datos de tu importación actual. 2️⃣ Guarda el archivo con un nombre que identifique la operación — por ejemplo: Importación_Enero2026_China o DAM-2026-000001. 3️⃣ Para tu próxima importación, abre el archivo original, haz una copia y renómbrala. De esta forma tendrás un historial ordenado de cada importación, con todos sus costos, tributos y márgenes guardados por separado. ✅ Así podrás comparar operaciones, identificar en cuál ganaste más y tomar mejores decisiones en cada nueva importación."
D5: → IMPORTANTE: Actualice el Tipo de Cambio USD→PEN antes de cada operación (fuente: SUNAT / BCR).
D6: → Configure los parámetros tributarios: Ad Valorem según partida arancelaria (0%, 6% u 11%), percepción según tipo de importador.
D7: → Tasas de percepción: 10% = primera importación / empresa nueva | 3.5% = producto nuevo importador frecuente | 5% = producto de segundo uso.
D9: PASO 2 — 🧾 FACTURA COMERCIAL
D10: → Ingrese cada producto: descripción, unidad de medida, cantidad total y precio FOB unitario en USD.
D11: → El sistema calcula automáticamente el FOB Total, el Factor de Prorrateo y el Costo Unitario.
D12: → Puede manejar hasta 30 productos diferentes en una misma importación.
D14: PASO 3 — 📦 GASTOS DE IMPORTACIÓN
D15: → Ingrese el monto de cada gasto pagado a los operadores: handling, descarga, tracción, almacenaje, transporte, etc.
D16: → Los gastos marcados ⭐ son afectos a IGV (18%) y generan crédito fiscal.
D17: → El Derecho de Emisión del Seguro y la Comisión del Agente se calculan automáticamente.
D18: → Complete también los gastos administrativos y financieros (transferencias, intereses de letras, carta de crédito).
... D49: ⚠️ Esta plantilla es una herramienta de estimación profesional — consulte siempre a un agente de aduanas certificado.

Sheet Doc. Necesarios
B2: DOCUMENTOS QUE DEBES DE TENER A LA MANO PARA LLENAR LA PLANTILLA
B4: 1 | C4: Proforma Comercial y/o Factura Invoice
B5: 2 | C5: Proforma o Liquidación del Agente de Aduana
C6: 2.1 | D6: Derechos de Aduana
C7: 2.2 | D7: Flete Internacional
C8: 2.3 | D8: Comisión del Agente
C9: 2.4 | D9: Gastos de Nacionalizacion
C10: 2.5 | D10: Transporte Interno

Sheet 📋 Datos Generales
D1: 📋 CALCULADORA DE COSTOS DE IMPORTACIÓN — PERÚ
D2: Complete los datos en AMARILLO 🟡. Los campos en VERDE 🟢 se calculan automáticamente.
D4: 📄 DATOS DE LA OPERACIÓN DE IMPORTACIÓN
D5: Número de DUA / DAM | E5: DAM-2025-000001
D6: Razón Social del Importador | E6: EMPRESA IMPORTADORA S.A.C.
D7: RUC del Importador | E7: 20XXXXXXXXX
D8: Fecha de Numeración DAM | E8: 24/02/2026
D9: País de Origen | E9: China
D10: Proveedor / Exportador | E10: HWPI Co. Ltd.
D11: Incoterm | E11: FOB
D12: Vía de Transporte | E12: Marítima
D13: Puerto de Embarque | E13: Shekou, China
D14: Puerto de Destino | E14: Callao, Perú
D15: Agente de Aduanas | E15: Agencia SAC
D16: Canal de Control | E16: Naranja
D18: ⚖️ PARÁMETROS TRIBUTARIOS (Configuración)
D19: Tipo de Cambio USD → PEN | E19: 3.72 | F19: Actualizar según SUNAT / BCR
D20: Ad Valorem — Arancel (%) | E20: 0.06 | F20: 0%, 6% u 11% según partida arancelaria
D21: IGV (%) | E21: 0.16 | F21: Fijo 16%
D22: IPM (%) | E22: 0.02 | F22: Fijo 2%
D23: Percepción IGV (%) | E23: 0.035 | F23: 10% nueva empresa / 3.5% producto nuevo / 5% segundo uso
D24: Prima Neta Seguro (%) | E24: 0 | F24: % sobre la Suma Asegurada
D25: Derecho de Emisión Seguro (%) | E25: 0 | F25: 3% sobre Prima Neta — negociable
D26: Deducible Seguro (%) | E26: 0 | F26: % del que somos responsables en siniestro
D27: Comisión Agente Aduanas (%) | E27: 0.01 | F27: % sobre CIF (mín. S/. 100)
D28: IGV Servicios (%) | E28: 0.18 | F28: 18% (IGV 16% + IPM 2%)
D30: 🟡 Amarillo = Dato editable 🟢 Verde = Calculado automáticamente 🔵 Azul = Total general

Sheet 🧾 Factura Comercial
D2: 🧾 FACTURA COMERCIAL — DETALLE DE PRODUCTOS
D3: Ingrese cada producto: descripción, unidad, cantidad y precio FOB unitario (USD).
D4: # | E4: DESCRIPCIÓN DEL PRODUCTO | F4: UNIDAD MEDIDA | G4: CANTIDAD (unid.) | H4: FOB UNIT. (USD) | I4: FOB TOTAL (USD) | J4: PARTICIPACIÓN | K4: COSTO UNIT. (PEN) | L4: PRECIO VENTA (PEN)
D5: 1 | E5: Case Transparente TPU iPhone 15 | F5: Unid. | G5: 480 | H5: 1.21 | I5: =IF(G5=0,0,G5*H5) -> 580.8 | J5: =IF(I5=0,0,I5/$I$35) -> 0.040861813 | K5: ='🧮 Costos x Producto'!K7 -> 5.886674 | L5: ='💰 Precio de Venta'!H8 -> 9.8111233
D6: 2 | E6: Cable USB-C Trenzado 1m | F6: Unid. | G6: 2880 | H6: 0.68 | I6: =IF(G6=0,0,G6*H6) -> 1958.4 | J6: =IF(I6=0,0,I6/$I$35) -> 0.13778198 | K6: ='🧮 Costos x Producto'!K8 -> 3.3082135 | L6: ='💰 Precio de Venta'!H9 -> 5.5136892
D7: 3 | E7: Protector Pantalla Vidrio Templado | F7: Unid. | G7: 2880 | H7: 0.4 | I7: =IF(G7=0,0,G7*H7) -> 1152 | J7: =IF(I7=0,0,I7/$I$35) -> 0.081048224 | K7: ='🧮 Costos x Producto'!K9 -> 1.9460079 | L7: ='💰 Precio de Venta'!H10 -> 3.2433466
D8: 4 | E8: Audífonos In-Ear con Micrófono | F8: Unid. | G8: 10224 | H8: 0.34 | I8: =IF(G8=0,0,G8*H8) -> 3476.16 | J8: =IF(I8=0,0,I8/$I$35) -> 0.24456301 | K8: ='🧮 Costos x Producto'!K10 -> 1.6541067 | L8: ='💰 Precio de Venta'!H11 -> 2.7568446
D9: 5 | E9: Cable Micro USB 2m Nylon | F9: Unid. | G9: 8640 | H9: 0.26 | I9: =IF(G9=0,0,G9*H9) -> 2246.4 | J9: =IF(I9=0,0,I9/$I$35) -> 0.15804404 | K9: ='🧮 Costos x Producto'!K11 -> 1.2649052 | L9: ='💰 Precio de Venta'!H12 -> 2.1081753
D10: 6 | E10: Soporte Anillo Pop Socket Metálico | F10: Unid. | G10: 2160 | H10: 0.29 | I10: =IF(G10=0,0,G10*H10) -> 626.4 | J10: =IF(I10=0,0,I10/$I$35) -> 0.044069972 | K10: ='🧮 Costos x Producto'!K12 -> 1.4108558 | L10: ='💰 Precio de Venta'!H13 -> 2.3514263
D11: 7 | E11: Cargador Inalámbrico 15W Qi | F11: Unid. | G11: 240 | H11: 5.71 | I11: =IF(G11=0,0,G11*H11) -> 1370.4 | J11: =IF(I11=0,0,I11/$I$35) -> 0.096413616 | K11: ='🧮 Costos x Producto'!K13 -> 27.779263 | L11: ='💰 Precio de Venta'!H14 -> 46.298772
D12: 8 | E12: Case Wallet Cuero PU Samsung S24 | F12: Unid. | G12: 1920 | H12: 0.76 | I12: =IF(G12=0,0,G12*H12) -> 1459.2 | J12: =IF(I12=0,0,I12/$I$35) -> 0.10266108 | K12: ='🧮 Costos x Producto'!K14 -> 3.6974151 | L12: ='💰 Precio de Venta'!H15 -> 6.1623585
D13: 9 | E13: Adaptador USB-C a Jack 3.5mm | F13: Unid. | G13: 4800 | H13: 0.28 | I13: =IF(G13=0,0,G13*H13) -> 1344 | J13: =IF(I13=0,0,I13/$I$35) -> 0.094556261 | K13: ='🧮 Costos x Producto'!K15 -> 1.3622056 | L13: ='💰 Precio de Venta'!H16 -> 2.2703426
D14: 10 | F14: Unid. | G14: 0 | H14: 0 | I14: =IF(G14=0,0,G14*H14) -> 0 | J14: =IF(I14=0,0,I14/$I$35) -> 0 | K14: ='🧮 Costos x Producto'!K16 -> 0 | L14: ='💰 Precio de Venta'!H17 -> 0
D15: 11 | F15: Unid. | G15: 0 | H15: 0 | I15: =IF(G15=0,0,G15*H15) -> 0 | J15: =IF(I15=0,0,I15/$I$35) -> 0 | K15: ='🧮 Costos x Producto'!K17 -> 0 | L15: ='💰 Precio de Venta'!H18 -> 0
D16: 12 | F16: Unid. | G16: 0 | H16: 0 | I16: =IF(G16=0,0,G16*H16) -> 0 | J16: =IF(I16=0,0,I16/$I$35) -> 0 | K16: ='🧮 Costos x Producto'!K18 -> 0 | L16: ='💰 Precio de Venta'!H19 -> 0
D17: 13 | F17: Unid. | G17: 0 | H17: 0 | I17: =IF(G17=0,0,G17*H17) -> 0 | J17: =IF(I17=0,0,I17/$I$35) -> 0 | K17: ='🧮 Costos x Producto'!K19 -> 0 | L17: ='💰 Precio de Venta'!H20 -> 0
D18: 14 | F18: Unid. | G18: 0 | H18: 0 | I18: =IF(G18=0,0,G18*H18) -> 0 | J18: =IF(I18=0,0,I18/$I$35) -> 0 | K18: ='🧮 Costos x Producto'!K20 -> 0 | L18: ='💰 Precio de Venta'!H21 -> 0
D19: 15 | F19: Unid. | G19: 0 | H19: 0 | I19: =IF(G19=0,0,G19*H19) -> 0 | J19: =IF(I19=0,0,I19/$I$35) -> 0 | K19: ='🧮 Costos x Producto'!K21 -> 0 | L19: ='💰 Precio de Venta'!H22 -> 0
D20: 16 | F20: Unid. | G20: 0 | H20: 0 | I20: =IF(G20=0,0,G20*H20) -> 0 | J20: =IF(I20=0,0,I20/$I$35) -> 0 | K20: ='🧮 Costos x Producto'!K22 -> 0 | L20: ='💰 Precio de Venta'!H23 -> 0
D21: 17 | F21: Unid. | G21: 0 | H21: 0 | I21: =IF(G21=0,0,G21*H21) -> 0 | J21: =IF(I21=0,0,I21/$I$35) -> 0 | K21: ='🧮 Costos x Producto'!K23 -> 0 | L21: ='💰 Precio de Venta'!H24 -> 0
D22: 18 | F22: Unid. | G22: 0 | H22: 0 | I22: =IF(G22=0,0,G22*H22) -> 0 | J22: =IF(I22=0,0,I22/$I$35) -> 0 | K22: ='🧮 Costos x Producto'!K24 -> 0 | L22: ='💰 Precio de Venta'!H25 -> 0
D23: 19 | F23: Unid. | G23: 0 | H23: 0 | I23: =IF(G23=0,0,G23*H23) -> 0 | J23: =IF(I23=0,0,I23/$I$35) -> 0 | K23: ='🧮 Costos x Producto'!K25 -> 0 | L23: ='💰 Precio de Venta'!H26 -> 0
D24: 20 | F24: Unid. | G24: 0 | H24: 0 | I24: =IF(G24=0,0,G24*H24) -> 0 | J24: =IF(I24=0,0,I24/$I$35) -> 0 | K24: ='🧮 Costos x Producto'!K26 -> 0 | L24: ='💰 Precio de Venta'!H27 -> 0
D25: 21 | F25: Unid. | G25: 0 | H25: 0 | I25: =IF(G25=0,0,G25*H25) -> 0 | J25: =IF(I25=0,0,I25/$I$35) -> 0 | K25: ='🧮 Costos x Producto'!K27 -> 0 | L25: ='💰 Precio de Venta'!H28 -> 0
... D34: 30 | F34: Unid. | G34: 0 | H34: 0 | I34: =IF(G34=0,0,G34*H34) -> 0 | J34: =IF(I34=0,0,I34/$I$35) -> 0 | K34: ='🧮 Costos x Producto'!K36 -> 0 | L34: ='💰 Precio de Venta'!H37 -> 0
D35: TOTAL FOB (USD) | I35: =SUM(I5:I34) -> 14213.76

Sheet 📦 Gastos Importación
D2: 📦 GASTOS DE IMPORTACIÓN (Tercer Elemento)
D3: Ingrese el monto de cada gasto. Los gastos marcados con ⭐ están sujetos a IGV del 18%.
D4: CONCEPTO / GASTO | E4: MONTO (USD) | F4: AFECTO IGV | G4: NOTAS
D5: ⭐ Derecho de Emisión (Seguro) | E5: ='🧾 Tributos Aduana'!F9 -> - | F5: SÍ | G5: Auto-calculado desde Tributos Aduana
D6: ⭐ Handling | E6: 34.03 | F6: SÍ | G6: Manipuleo de la carga
D7: ⭐ Servicio de Descarga | E7: 100.69 | F7: SÍ | G7: Descarga del contenedor
D8: ⭐ Movilización de Carga | E8: 36.46 | F8: SÍ | G8: Traslado interno del terminal
D9: ⭐ Tracción | E9: 48.61 | F9: SÍ | G9: Transporte del contenedor
D10: ⭐ Servicio al Cliente (V°B°) | E10: 12.15 | F10: SÍ | G10: Verificación de pago del flete
D11: ⭐ Gastos Operativos Agente | E11: 70 | F11: SÍ | G11: Gestión del despacho
D12: ⭐ Almacenaje | E12: 121.53 | F12: SÍ | G12: Días de almacén temporal
D13: ⭐ Cargadores / Cuadrilla | E13: 62.5 | F13: SÍ | G13: Personal de carga
D14: ⭐ Serv. Administrativos | E14: 13.89 | F14: SÍ | G14: Documentación
D15: ⭐ Seguro de Contenedor | E15: 41.67 | F15: SÍ | G15: Seguro de la carga en tránsito local
D16: ⭐ Posicionamiento de Carga | E16: 62.5 | F16: SÍ | G16: Reconocimiento físico si aplica
D17: ⭐ Transporte Interno / Última Milla | E17: 104.17 | F17: SÍ | G17: Traslado a almacenes del importador
... D25: Comisiones C/C | E25: 0 | F25: NO | G25: 1.2% CFR si aplica carta de crédito
D26: SUB-TOTAL AFECTOS A IGV (US$) | E26: =E6+E7+E8+E9+E10+E11+E12+E13+E14+E15+E16+E17+E18+E19+E20 -> 997.24 | F26: =SUM(E6:E20)*'📋 Datos Generales'!E28 -> 179.5032
D27: SUB-TOTAL NO AFECTOS A IGV (US$) | E27: =E21+E22+E23+E24+E25 -> 167.5 | F27: No genera IGV
D28: ⭐ TOTAL COSTOS IMPORTACIÓN (US$) | E28: ='🧾 Tributos Aduana'!$F$14+'🧾 Tributos Aduana'!$F$17+E26+E27 -> 18588.77
H30: Tipo | I30: US$
H31: Afectos IGV | I31: =E26 -> 997.24
H32: No Afectos | I32: =E27 -> 167.5

Sheet 🧾 Tributos Aduana
E2: 🧾 TRIBUTOS ADUANEROS — CÁLCULO AUTOMÁTICO
E3: Todos los valores se calculan automáticamente. Solo configure los parámetros en '📋 Datos Generales'.
E5: 🛡️ CÁLCULO DEL SEGURO (Prima Neta → Suma Asegurada)
E6: FOB Total (USD) | F6: ='🧾 Factura Comercial'!I35 -> 14213.76 | G6: Valor FOB total de la factura comercial
E7: Flete Internacional (USD) | F7: 2090 | G7: Monto del flete — copiar del BL/AWB
E8: CFR = FOB + Flete (USD) | F8: =F6+F7 -> 16303.76 | G8: Valor CFR = base para calcular SA
E9: Suma Asegurada (USD) | F9: - | G9: SA = CFR / (1 - deducible%) — Fórmula del libro
E10: Prima Neta (USD) | F10: 134.27 | G10: Prima Neta = SA × 24%
E11: D. Emisión Seguro (USD) | F11: =F10*'📋 Datos Generales'!E25 -> 0 | G11: Derecho de Emisión = 3% × Prima Neta → va a Gastos
E12: IGV Seguro (USD) | F12: =SUM(F10:F11)*'📋 Datos Generales'!E28 -> 24.1686 | G12: IGV sobre Prima Neta → va a Crédito Fiscal
E13: Seguro (Prima Neta) → CIF | F13: =F10 -> 134.27 | G13: Prima Neta forma parte del CIF
E14: CIF = CFR + Prima Neta | F14: =F8+F10 -> 16438.03 | G14: CIF = Valor en Aduanas
E16: ⚖️ DEUDA ADUANERA (ADEUDO) — Pago a SUNAT-ADUANAS
E17: Ad Valorem — ADV (USD) | F17: =ROUND(F14*'📋 Datos Generales'!E20,0) -> 986 | G17: ADV = CIF × Ad Valorem% — redondeado entero
E18: IPM (USD) | F18: =ROUND((F14+F17)*'📋 Datos Generales'!E22,0) -> 348 | G18: IPM = (CIF + ADV) × 2% — redondeado
E19: IGV (USD) | F19: =ROUND((F14+F17)*'📋 Datos Generales'!E21,0) -> 2788 | G19: IGV = (CIF + ADV) × 16% — redondeado
E20: DEUDA ADUANERA = DA (USD) | F20: =F17+F18+F19 -> 4122 | G20: DA = ADV + IPM + IGV
E22: 💸 PERCEPCIÓN IGV Y DERECHOS (costo real)
E23: Percepción IGV (USD) | F23: =ROUND((F14+F20)*'📋 Datos Generales'!E23,2) -> 719.6 | G23: Base = CIF + DA — tasa según tipo importador
E24: DERECHOS = ADV (USD) | F24: =F17 -> 986 | G24: Solo el ADV es costo (IPM e IGV = crédito fiscal)
E25: Comisión Agente (USD) | F25: =MAX(F14*'📋 Datos Generales'!E27,100/'📋 Datos Generales'!E19) -> 164.3803 | G25: Máx entre 1% CIF y mín USD 100
F35: Componente | G35: Monto US$
F36: Ad Valorem | G36: =F17 -> 986
F37: IPM | G37: =F18 -> 348
F38: IGV Aduanas | G38: =F19 -> 2788
F39: Percepción | G39: =F23 -> 719.6
F42: Componente | G42: Monto US$
F43: FOB | G43: =F6 -> 14213.76
F44: Flete | G44: =F7 -> 2090
F45: Seguro | G45: =F10 -> 134.27

Sheet 🧮 Costos x Producto
D2: 🧮 COSTO DE IMPORTACIÓN POR PRODUCTO (Factor de Prorrateo)
D3: El Costo Unitario se calcula multiplicando el Factor de Prorrateo × FOB Unitario. Factor = C/M Total / FOB Total
D4: COSTO TOTAL DE IMPORTACIÓN (US$) | G4: ='📦 Gastos Importación'!E28 -> 18588.77 | I4: =G4*'📋 Datos Generales'!E19 -> 69150.224
D5: FACTOR DE PRORRATEO = C/M Total (US$) / FOB Total (US$) | G5: =IF('🧾 Factura Comercial'!I35=0,0,G4/'🧾 Factura Comercial'!I35) -> 1.307801
D6: # | E6: PRODUCTO | F6: CANTIDAD | G6: FOB UNIT. (USD) | H6: FOB TOTAL (USD) | I6: % PARTICIPACÓN | J6: C/M UNIT. (USD) | K6: C/M UNIT. (PEN)
D7: 1 | E7: ='🧾 Factura Comercial'!E5 -> Case Transparente TPU iPhone 15 | F7: ='🧾 Factura Comercial'!G5 -> 480 | G7: ='🧾 Factura Comercial'!H5 -> 1.21 | H7: ='🧾 Factura Comercial'!I5 -> 580.8 | I7: ='🧾 Factura Comercial'!J5 -> 0.040861813 | J7: =IF(G5=0,0,G5*G7) -> 1.5824392 | K7: =J7*'📋 Datos Generales'!E19 -> 5.886674
D8: 2 | E8: ='🧾 Factura Comercial'!E6 -> Cable USB-C Trenzado 1m | F8: ='🧾 Factura Comercial'!G6 -> 2880 | G8: ='🧾 Factura Comercial'!H6 -> 0.68 | H8: ='🧾 Factura Comercial'!I6 -> 1958.4 | I8: ='🧾 Factura Comercial'!J6 -> 0.13778198 | J8: =IF(G5=0,0,G5*G8) -> 0.8893047 | K8: =J8*'📋 Datos Generales'!E19 -> 3.3082135
D9: 3 | E9: ='🧾 Factura Comercial'!E7 -> Protector Pantalla Vidrio Templado | F9: ='🧾 Factura Comercial'!G7 -> 2880 | G9: ='🧾 Factura Comercial'!H7 -> 0.4 | H9: ='🧾 Factura Comercial'!I7 -> 1152 | I9: ='🧾 Factura Comercial'!J7 -> 0.081048224 | J9: =IF(G5=0,0,G5*G9) -> 0.52312041 | K9: =J9*'📋 Datos Generales'!E19 -> 1.9460079
D10: 4 | E10: ='🧾 Factura Comercial'!E8 -> Audífonos In-Ear con Micrófono | F10: ='🧾 Factura Comercial'!G8 -> 10224 | G10: ='🧾 Factura Comercial'!H8 -> 0.34 | H10: ='🧾 Factura Comercial'!I8 -> 3476.16 | I10: ='🧾 Factura Comercial'!J8 -> 0.24456301 | J10: =IF(G5=0,0,G5*G10) -> 0.44465235 | K10: =J10*'📋 Datos Generales'!E19 -> 1.6541067
D11: 5 | E11: ='🧾 Factura Comercial'!E9 -> Cable Micro USB 2m Nylon | F11: ='🧾 Factura Comercial'!G9 -> 8640 | G11: ='🧾 Factura Comercial'!H9 -> 0.26 | H11: ='🧾 Factura Comercial'!I9 -> 2246.4 | I11: ='🧾 Factura Comercial'!J9 -> 0.15804404 | J11: =IF(G5=0,0,G5*G11) -> 0.34002827 | K11: =J11*'📋 Datos Generales'!E19 -> 1.2649052
D12: 6 | E12: ='🧾 Factura Comercial'!E10 -> Soporte Anillo Pop Socket Metálico | F12: ='🧾 Factura Comercial'!G10 -> 2160 | G12: ='🧾 Factura Comercial'!H10 -> 0.29 | H12: ='🧾 Factura Comercial'!I10 -> 626.4 | I12: ='🧾 Factura Comercial'!J10 -> 0.044069972 | J12: =IF(G5=0,0,G5*G12) -> 0.3792623 | K12: =J12*'📋 Datos Generales'!E19 -> 1.4108558
D13: 7 | E13: ='🧾 Factura Comercial'!E11 -> Cargador Inalámbrico 15W Qi | F13: ='🧾 Factura Comercial'!G11 -> 240 | G13: ='🧾 Factura Comercial'!H11 -> 5.71 | H13: ='🧾 Factura Comercial'!I11 -> 1370.4 | I13: ='🧾 Factura Comercial'!J11 -> 0.096413616 | J13: =IF(G5=0,0,G5*G13) -> 7.4675439 | K13: =J13*'📋 Datos Generales'!E19 -> 27.779263
D14: 8 | E14: ='🧾 Factura Comercial'!E12 -> Case Wallet Cuero PU Samsung S24 | F14: ='🧾 Factura Comercial'!G12 -> 1920 | G14: ='🧾 Factura Comercial'!H12 -> 0.76 | H14: ='🧾 Factura Comercial'!I12 -> 1459.2 | I14: ='🧾 Factura Comercial'!J12 -> 0.10266108 | J14: =IF(G5=0,0,G5*G14) -> 0.99392878 | K14: =J14*'📋 Datos Generales'!E19 -> 3.6974151
D15: 9 | E15: ='🧾 Factura Comercial'!E13 -> Adaptador USB-C a Jack 3.5mm | F15: ='🧾 Factura Comercial'!G13 -> 4800 | G15: ='🧾 Factura Comercial'!H13 -> 0.28 | H15: ='🧾 Factura Comercial'!I13 -> 1344 | I15: ='🧾 Factura Comercial'!J13 -> 0.094556261 | J15: =IF(G5=0,0,G5*G15) -> 0.36618429 | K15: =J15*'📋 Datos Generales'!E19 -> 1.3622056
D16: 10 | E16: ='🧾 Factura Comercial'!E14 -> 0 | F16: ='🧾 Factura Comercial'!G14 -> 0 | G16: ='🧾 Factura Comercial'!H14 -> 0 | H16: ='🧾 Factura Comercial'!I14 -> 0 | I16: ='🧾 Factura Comercial'!J14 -> 0 | J16: =IF(G5=0,0,G5*G16) -> 0 | K16: =J16*'📋 Datos Generales'!E19 -> 0
D17: 11 | E17: ='🧾 Factura Comercial'!E15 -> 0 | F17: ='🧾 Factura Comercial'!G15 -> 0 | G17: ='🧾 Factura Comercial'!H15 -> 0 | H17: ='🧾 Factura Comercial'!I15 -> 0 | I17: ='🧾 Factura Comercial'!J15 -> 0 | J17: =IF(G5=0,0,G5*G17) -> 0 | K17: =J17*'📋 Datos Generales'!E19 -> 0
D18: 12 | E18: ='🧾 Factura Comercial'!E16 -> 0 | F18: ='🧾 Factura Comercial'!G16 -> 0 | G18: ='🧾 Factura Comercial'!H16 -> 0 | H18: ='🧾 Factura Comercial'!I16 -> 0 | I18: ='🧾 Factura Comercial'!J16 -> 0 | J18: =IF(G5=0,0,G5*G18) -> 0 | K18: =J18*'📋 Datos Generales'!E19 -> 0
D19: 13 | E19: ='🧾 Factura Comercial'!E17 -> 0 | F19: ='🧾 Factura Comercial'!G17 -> 0 | G19: ='🧾 Factura Comercial'!H17 -> 0 | H19: ='🧾 Factura Comercial'!I17 -> 0 | I19: ='🧾 Factura Comercial'!J17 -> 0 | J19: =IF(G5=0,0,G5*G19) -> 0 | K19: =J19*'📋 Datos Generales'!E19 -> 0
D20: 14 | E20: ='🧾 Factura Comercial'!E18 -> 0 | F20: ='🧾 Factura Comercial'!G18 -> 0 | G20: ='🧾 Factura Comercial'!H18 -> 0 | H20: ='🧾 Factura Comercial'!I18 -> 0 | I20: ='🧾 Factura Comercial'!J18 -> 0 | J20: =IF(G5=0,0,G5*G20) -> 0 | K20: =J20*'📋 Datos Generales'!E19 -> 0
D21: 15 | E21: ='🧾 Factura Comercial'!E19 -> 0 | F21: ='🧾 Factura Comercial'!G19 -> 0 | G21: ='🧾 Factura Comercial'!H19 -> 0 | H21: ='🧾 Factura Comercial'!I19 -> 0 | I21: ='🧾 Factura Comercial'!J19 -> 0 | J21: =IF(G5=0,0,G5*G21) -> 0 | K21: =J21*'📋 Datos Generales'!E19 -> 0
D22: 16 | E22: ='🧾 Factura Comercial'!E20 -> 0 | F22: ='🧾 Factura Comercial'!G20 -> 0 | G22: ='🧾 Factura Comercial'!H20 -> 0 | H22: ='🧾 Factura Comercial'!I20 -> 0 | I22: ='🧾 Factura Comercial'!J20 -> 0 | J22: =IF(G5=0,0,G5*G22) -> 0 | K22: =J22*'📋 Datos Generales'!E19 -> 0
D23: 17 | E23: ='🧾 Factura Comercial'!E21 -> 0 | F23: ='🧾 Factura Comercial'!G21 -> 0 | G23: ='🧾 Factura Comercial'!H21 -> 0 | H23: ='🧾 Factura Comercial'!I21 -> 0 | I23: ='🧾 Factura Comercial'!J21 -> 0 | J23: =IF(G5=0,0,G5*G23) -> 0 | K23: =J23*'📋 Datos Generales'!E19 -> 0
D24: 18 | E24: ='🧾 Factura Comercial'!E22 -> 0 | F24: ='🧾 Factura Comercial'!G22 -> 0 | G24: ='🧾 Factura Comercial'!H22 -> 0 | H24: ='🧾 Factura Comercial'!I22 -> 0 | I24: ='🧾 Factura Comercial'!J22 -> 0 | J24: =IF(G5=0,0,G5*G24) -> 0 | K24: =J24*'📋 Datos Generales'!E19 -> 0
D25: 19 | E25: ='🧾 Factura Comercial'!E23 -> 0 | F25: ='🧾 Factura Comercial'!G23 -> 0 | G25: ='🧾 Factura Comercial'!H23 -> 0 | H25: ='🧾 Factura Comercial'!I23 -> 0 | I25: ='🧾 Factura Comercial'!J23 -> 0 | J25: =IF(G5=0,0,G5*G25) -> 0 | K25: =J25*'📋 Datos Generales'!E19 -> 0
D26: 20 | E26: ='🧾 Factura Comercial'!E24 -> 0 | F26: ='🧾 Factura Comercial'!G24 -> 0 | G26: ='🧾 Factura Comercial'!H24 -> 0 | H26: ='🧾 Factura Comercial'!I24 -> 0 | I26: ='🧾 Factura Comercial'!J24 -> 0 | J26: =IF(G5=0,0,G5*G26) -> 0 | K26: =J26*'📋 Datos Generales'!E19 -> 0
D27: 21 | E27: ='🧾 Factura Comercial'!E25 -> 0 | F27: ='🧾 Factura Comercial'!G25 -> 0 | G27: ='🧾 Factura Comercial'!H25 -> 0 | H27: ='🧾 Factura Comercial'!I25 -> 0 | I27: ='🧾 Factura Comercial'!J25 -> 0 | J27: =IF(G5=0,0,G5*G27) -> 0 | K27: =J27*'📋 Datos Generales'!E19 -> 0
D28: 22 | E28: ='🧾 Factura Comercial'!E26 -> 0 | F28: ='🧾 Factura Comercial'!G26 -> 0 | G28: ='🧾 Factura Comercial'!H26 -> 0 | H28: ='🧾 Factura Comercial'!I26 -> 0 | I28: ='🧾 Factura Comercial'!J26 -> 0 | J28: =IF(G5=0,0,G5*G28) -> 0 | K28: =J28*'📋 Datos Generales'!E19 -> 0
D29: 23 | E29: ='🧾 Factura Comercial'!E27 -> 0 | F29: ='🧾 Factura Comercial'!G27 -> 0 | G29: ='🧾 Factura Comercial'!H27 -> 0 | H29: ='🧾 Factura Comercial'!I27 -> 0 | I29: ='🧾 Factura Comercial'!J27 -> 0 | J29: =IF(G5=0,0,G5*G29) -> 0 | K29: =J29*'📋 Datos Generales'!E19 -> 0
D30: 24 | E30: ='🧾 Factura Comercial'!E28 -> 0 | F30: ='🧾 Factura Comercial'!G28 -> 0 | G30: ='🧾 Factura Comercial'!H28 -> 0 | H30: ='🧾 Factura Comercial'!I28 -> 0 | I30: ='🧾 Factura Comercial'!J28 -> 0 | J30: =IF(G5=0,0,G5*G30) -> 0 | K30: =J30*'📋 Datos Generales'!E19 -> 0
D31: 25 | E31: ='🧾 Factura Comercial'!E29 -> 0 | F31: ='🧾 Factura Comercial'!G29 -> 0 | G31: ='🧾 Factura Comercial'!H29 -> 0 | H31: ='🧾 Factura Comercial'!I29 -> 0 | I31: ='🧾 Factura Comercial'!J29 -> 0 | J31: =IF(G5=0,0,G5*G31) -> 0 | K31: =J31*'📋 Datos Generales'!E19 -> 0
D32: 26 | E32: ='🧾 Factura Comercial'!E30 -> 0 | F32: ='🧾 Factura Comercial'!G30 -> 0 | G32: ='🧾 Factura Comercial'!H30 -> 0 | H32: ='🧾 Factura Comercial'!I30 -> 0 | I32: ='🧾 Factura Comercial'!J30 -> 0 | J32: =IF(G5=0,0,G5*G32) -> 0 | K32: =J32*'📋 Datos Generales'!E19 -> 0
D33: 27 | E33: ='🧾 Factura Comercial'!E31 -> 0 | F33: ='🧾 Factura Comercial'!G31 -> 0 | G33: ='🧾 Factura Comercial'!H31 -> 0 | H33: ='🧾 Factura Comercial'!I31 -> 0 | I33: ='🧾 Factura Comercial'!J31 -> 0 | J33: =IF(G5=0,0,G5*G33) -> 0 | K33: =J33*'📋 Datos Generales'!E19 -> 0
D34: 28 | E34: ='🧾 Factura Comercial'!E32 -> 0 | F34: ='🧾 Factura Comercial'!G32 -> 0 | G34: ='🧾 Factura Comercial'!H32 -> 0 | H34: ='🧾 Factura Comercial'!I32 -> 0 | I34: ='🧾 Factura Comercial'!J32 -> 0 | J34: =IF(G5=0,0,G5*G34) -> 0 | K34: =J34*'📋 Datos Generales'!E19 -> 0
D35: 29 | E35: ='🧾 Factura Comercial'!E33 -> 0 | F35: ='🧾 Factura Comercial'!G33 -> 0 | G35: ='🧾 Factura Comercial'!H33 -> 0 | H35: ='🧾 Factura Comercial'!I33 -> 0 | I35: ='🧾 Factura Comercial'!J33 -> 0 | J35: =IF(G5=0,0,G5*G35) -> 0 | K35: =J35*'📋 Datos Generales'!E19 -> 0
D36: 30 | E36: ='🧾 Factura Comercial'!E34 -> 0 | F36: ='🧾 Factura Comercial'!G34 -> 0 | G36: ='🧾 Factura Comercial'!H34 -> 0 | H36: ='🧾 Factura Comercial'!I34 -> 0 | I36: ='🧾 Factura Comercial'!J34 -> 0 | J36: =IF(G5=0,0,G5*G36) -> 0 | K36: =J36*'📋 Datos Generales'!E19 -> 0

Sheet 💰 Precio de Venta
D2: 💰 PRECIO DE VENTA — POLÍTICA DE UTILIDADES
D3: Ingrese su margen de ganancia deseado. VV = Costo Total / (1 - Margen%) — Precio de Venta incluye IGV (18%).
D4: MARGEN DE UTILIDAD GLOBAL (aplica a todos — puedes personalizar por producto ↓) | H4: 0.4
D5: VALOR DE VENTA TOTAL SIN IGV USD | H5: ='📦 Gastos Importación'!E28*H4 -> 7435.508
D6: FACTOR DE PRORRATEO = PV TOTAL / FOB TOTAL | H6: =('📦 Gastos Importación'!E28+H5)/'🧾 Factura Comercial'!I35 -> 1.8309214
D7: # | E7: PRODUCTO | F7: C/M UNIT. (PEN) | G7: MARGEN % | H7: VALOR VENTA UNIT. (S/.) | I7: PRECIO VENTA UNIT. c/IGV (S/.) | J7: GANANCIA UNIT. (S/.) | K7: PUNTO EQUILIBRIO
D8: 1 | E8: ='🧾 Factura Comercial'!E5 -> Case Transparente TPU iPhone 15 | F8: ='🧮 Costos x Producto'!K7 -> 5.886674 | G8: =$H$4 -> 0.4 | H8: =IF(F8=0,0,F8/(1-G8)) -> 9.8111233 | I8: =IF(H8=0,0,H8*(1+'📋 Datos Generales'!$E$28)) -> 11.577126 | J8: =IF(H8=0,0,H8-F8) -> 3.9244493 | K8: =IF(OR(I8=0,'🧾 Factura Comercial'!G5=0),0,CEILING('🧮 Costos x Producto'!J7*'🧾 Factura Comercial'!G5/I8,1)) -> 66
D9: 2 | E9: ='🧾 Factura Comercial'!E6 -> Cable USB-C Trenzado 1m | F9: ='🧮 Costos x Producto'!K8 -> 3.3082135 | G9: =$H$4 -> 0.4 | H9: =IF(F9=0,0,F9/(1-G9)) -> 5.5136892 | I9: =IF(H9=0,0,H9*(1+'📋 Datos Generales'!$E$28)) -> 6.5061532 | J9: =IF(H9=0,0,H9-F9) -> 2.2054757 | K9: =IF(OR(I9=0,'🧾 Factura Comercial'!G6=0),0,CEILING('🧮 Costos x Producto'!J8*'🧾 Factura Comercial'!G6/I9,1)) -> 394
D10: 3 | E10: ='🧾 Factura Comercial'!E7 -> Protector Pantalla Vidrio Templado | F10: ='🧮 Costos x Producto'!K9 -> 1.9460079 | G10: 0.4 | H10: =IF(F10=0,0,F10/(1-G10)) -> 3.2433466 | I10: =IF(H10=0,0,H10*(1+'📋 Datos Generales'!$E$28)) -> 3.8271489 | J10: =IF(H10=0,0,H10-F10) -> 1.2973386 | K10: =IF(OR(I10=0,'🧾 Factura Comercial'!G7=0),0,CEILING('🧮 Costos x Producto'!J9*'🧾 Factura Comercial'!G7/I10,1)) -> 394
D11: 4 | E11: ='🧾 Factura Comercial'!E8 -> Audífonos In-Ear con Micrófono | F11: ='🧮 Costos x Producto'!K10 -> 1.6541067 | G11: =$H$4 -> 0.4 | H11: =IF(F11=0,0,F11/(1-G11)) -> 2.7568446 | I11: =IF(H11=0,0,H11*(1+'📋 Datos Generales'!$E$28)) -> 3.2530766 | J11: =IF(H11=0,0,H11-F11) -> 1.1027378 | K11: =IF(OR(I11=0,'🧾 Factura Comercial'!G8=0),0,CEILING('🧮 Costos x Producto'!J10*'🧾 Factura Comercial'!G8/I11,1)) -> 1398
D12: 5 | E12: ='🧾 Factura Comercial'!E9 -> Cable Micro USB 2m Nylon | F12: ='🧮 Costos x Producto'!K11 -> 1.2649052 | G12: =$H$4 -> 0.4 | H12: =IF(F12=0,0,F12/(1-G12)) -> 2.1081753 | I12: =IF(H12=0,0,H12*(1+'📋 Datos Generales'!$E$28)) -> 2.4876468 | J12: =IF(H12=0,0,H12-F12) -> 0.84327011 | K12: =IF(OR(I12=0,'🧾 Factura Comercial'!G9=0),0,CEILING('🧮 Costos x Producto'!J11*'🧾 Factura Comercial'!G9/I12,1)) -> 1181
D13: 6 | E13: ='🧾 Factura Comercial'!E10 -> Soporte Anillo Pop Socket Metálico | F13: ='🧮 Costos x Producto'!K12 -> 1.4108558 | G13: =$H$4 -> 0.4 | H13: =IF(F13=0,0,F13/(1-G13)) -> 2.3514263 | I13: =IF(H13=0,0,H13*(1+'📋 Datos Generales'!$E$28)) -> 2.774683 | J13: =IF(H13=0,0,H13-F13) -> 0.9405705 | K13: =IF(OR(I13=0,'🧾 Factura Comercial'!G10=0),0,CEILING('🧮 Costos x Producto'!J12*'🧾 Factura Comercial'!G10/I13,1)) -> 296
D14: 7 | E14: ='🧾 Factura Comercial'!E11 -> Cargador Inalámbrico 15W Qi | F14: ='🧮 Costos x Producto'!K13 -> 27.779263 | G14: =$H$4 -> 0.4 | H14: =IF(F14=0,0,F14/(1-G14)) -> 46.298772 | I14: =IF(H14=0,0,H14*(1+'📋 Datos Generales'!$E$28)) -> 54.632551 | J14: =IF(H14=0,0,H14-F14) -> 18.519509 | K14: =IF(OR(I14=0,'🧾 Factura Comercial'!G11=0),0,CEILING('🧮 Costos x Producto'!J13*'🧾 Factura Comercial'!G11/I14,1)) -> 33
D15: 8 | E15: ='🧾 Factura Comercial'!E12 -> Case Wallet Cuero PU Samsung S24 | F15: ='🧮 Costos x Producto'!K14 -> 3.6974151 | G15: =$H$4 -> 0.4 | H15: =IF(F15=0,0,F15/(1-G15)) -> 6.1623585 | I15: =IF(H15=0,0,H15*(1+'📋 Datos Generales'!$E$28)) -> 7.271583 | J15: =IF(H15=0,0,H15-F15) -> 2.4649434 | K15: =IF(OR(I15=0,'🧾 Factura Comercial'!G12=0),0,CEILING('🧮 Costos x Producto'!J14*'🧾 Factura Comercial'!G12/I15,1)) -> 263
D16: 9 | E16: ='🧾 Factura Comercial'!E13 -> Adaptador USB-C a Jack 3.5mm | F16: ='🧮 Costos x Producto'!K15 -> 1.3622056 | G16: =$H$4 -> 0.4 | H16: =IF(F16=0,0,F16/(1-G16)) -> 2.2703426 | I16: =IF(H16=0,0,H16*(1+'📋 Datos Generales'!$E$28)) -> 2.6790043 | J16: =IF(H16=0,0,H16-F16) -> 0.90813704 | K16: =IF(OR(I16=0,'🧾 Factura Comercial'!G13=0),0,CEILING('🧮 Costos x Producto'!J15*'🧾 Factura Comercial'!G13/I16,1)) -> 657
D17: 10 | E17: ='🧾 Factura Comercial'!E14 -> 0 | F17: ='🧮 Costos x Producto'!K16 -> 0 | G17: =$H$4 -> 0.4 | H17: =IF(F17=0,0,F17/(1-G17)) -> 0 | I17: =IF(H17=0,0,H17*(1+'📋 Datos Generales'!$E$28)) -> 0 | J17: =IF(H17=0,0,H17-F17) -> 0 | K17: =IF(OR(I17=0,'🧾 Factura Comercial'!G14=0),0,CEILING('🧮 Costos x Producto'!J16*'🧾 Factura Comercial'!G14/I17,1)) -> 0
D18: 11 | E18: ='🧾 Factura Comercial'!E15 -> 0 | F18: ='🧮 Costos x Producto'!K17 -> 0 | G18: =$H$4 -> 0.4 | H18: =IF(F18=0,0,F18/(1-G18)) -> 0 | I18: =IF(H18=0,0,H18*(1+'📋 Datos Generales'!$E$28)) -> 0 | J18: =IF(H18=0,0,H18-F18) -> 0 | K18: =IF(OR(I18=0,'🧾 Factura Comercial'!G15=0),0,CEILING('🧮 Costos x Producto'!J17*'🧾 Factura Comercial'!G15/I18,1)) -> 0
D19: 12 | E19: ='🧾 Factura Comercial'!E16 -> 0 | F19: ='🧮 Costos x Producto'!K18 -> 0 | G19: =$H$4 -> 0.4 | H19: =IF(F19=0,0,F19/(1-G19)) -> 0 | I19: =IF(H19=0,0,H19*(1+'📋 Datos Generales'!$E$28)) -> 0 | J19: =IF(H19=0,0,H19-F19) -> 0 | K19: =IF(OR(I19=0,'🧾 Factura Comercial'!G16=0),0,CEILING('🧮 Costos x Producto'!J18*'🧾 Factura Comercial'!G16/I19,1)) -> 0
D20: 13 | E20: ='🧾 Factura Comercial'!E17 -> 0 | F20: ='🧮 Costos x Producto'!K19 -> 0 | G20: =$H$4 -> 0.4 | H20: =IF(F20=0,0,F20/(1-G20)) -> 0 | I20: =IF(H20=0,0,H20*(1+'📋 Datos Generales'!$E$28)) -> 0 | J20: =IF(H20=0,0,H20-F20) -> 0 | K20: =IF(OR(I20=0,'🧾 Factura Comercial'!G17=0),0,CEILING('🧮 Costos x Producto'!J19*'🧾 Factura Comercial'!G17/I20,1)) -> 0
D21: 14 | E21: ='🧾 Factura Comercial'!E18 -> 0 | F21: ='🧮 Costos x Producto'!K20 -> 0 | G21: =$H$4 -> 0.4 | H21: =IF(F21=0,0,F21/(1-G21)) -> 0 | I21: =IF(H21=0,0,H21*(1+'📋 Datos Generales'!$E$28)) -> 0 | J21: =IF(H21=0,0,H21-F21) -> 0 | K21: =IF(OR(I21=0,'🧾 Factura Comercial'!G18=0),0,CEILING('🧮 Costos x Producto'!J20*'🧾 Factura Comercial'!G18/I21,1)) -> 0
D22: 15 | E22: ='🧾 Factura Comercial'!E19 -> 0 | F22: ='🧮 Costos x Producto'!K21 -> 0 | G22: =$H$4 -> 0.4 | H22: =IF(F22=0,0,F22/(1-G22)) -> 0 | I22: =IF(H22=0,0,H22*(1+'📋 Datos Generales'!$E$28)) -> 0 | J22: =IF(H22=0,0,H22-F22) -> 0 | K22: =IF(OR(I22=0,'🧾 Factura Comercial'!G19=0),0,CEILING('🧮 Costos x Producto'!J21*'🧾 Factura Comercial'!G19/I22,1)) -> 0
... D37: 30 | E37: ='🧾 Factura Comercial'!E34 -> 0 | F37: ='🧮 Costos x Producto'!K36 -> 0 | G37: =$H$4 -> 0.4 | H37: =IF(F37=0,0,F37/(1-G37)) -> 0 | I37: =IF(H37=0,0,H37*(1+'📋 Datos Generales'!$E$28)) -> 0 | J37: =IF(H37=0,0,H37-F37) -> 0 | K37: =IF(OR(I37=0,'🧾 Factura Comercial'!G34=0),0,CEILING('🧮 Costos x Producto'!J36*'🧾 Factura Comercial'!G34/I37,1)) -> 0

Sheet 🏦 Crédito Fiscal
B7: 🏦 CRÉDITO FISCAL DEL IMPORTADOR
B8: El Crédito Fiscal se recupera al vender los productos. IPM, IGV y Percepción NO son costo — se recuperan.
B10: 🏦 DETALLE DEL CRÉDITO FISCAL (en US$ — convertir a S/. con TC)
B11: IGV del Seguro (Crédito Fiscal) | C11: ='🧾 Tributos Aduana'!F12 -> 24.1686 | D11: IGV pagado a Cía. de Seguros
B12: IPM — Derechos (Crédito Fiscal) | C12: ='🧾 Tributos Aduana'!F18 -> 348 | D12: IPM pagado a SUNAT-Aduanas
B13: IGV — Derechos (Crédito Fiscal) | C13: ='🧾 Tributos Aduana'!F19 -> 2788 | D13: IGV pagado a SUNAT-Aduanas
B14: Percepción IGV (Crédito Fiscal) | C14: ='🧾 Tributos Aduana'!F23 -> 719.6 | D14: Percepción pagada — se recupera
B15: IGV Gastos Afectos (Crédito Fiscal) | C15: ='📦 Gastos Importación'!F26 -> 179.5032 | D15: 18% de gastos afectos
B16: ✅ TOTAL CRÉDITO FISCAL (US$) | C16: =C11+C12+C13+C14+C15 -> 4059.2718
B17: ✅ TOTAL CRÉDITO FISCAL (S/. PEN) | C17: =C16*'📋 Datos Generales'!E19 -> 15100.491
B19: 📌 ¿QUÉ ES EL CRÉDITO FISCAL? El IGV, IPM y la Percepción que pagas al importar NO son un costo definitivo. Los recuperas cuando vendes tus productos y cobras IGV a tus clientes. El importador declara ante SUNAT: IGV cobrado en ventas - Crédito Fiscal = IGV a pagar. ⚠️ SOLO el Ad Valorem (ADV) es un costo real de importación.

Sheet Detallado por producto
B1: 📦 SECCIÓN 1: IDENTIFICACIÓN DEL PRODUCTO Y VALOR FOB | AE1: 🧮 SECCIÓN 3: COSTO DE IMPORTACIÓN · CRÉDITO FISCAL · PRECIO DE VENTA · MARGENARGEN
A2: DESCRIPCIÓN DEL PRODUCTO | B2: UNIDAD | C2: CANTIDAD (unid.) | D2: FOB UNIT. (US$) | E2: FOB TOTAL (US$) | F2: % PART. FOB | G2: FOB UNIT. (S/.) | H2: FOB TOTAL (S/.) | I2: ADV UNIT. (US$) ⚠️COSTO | J2: ADV TOTAL (US$) ⚠️COSTO | K2: IPM UNIT. (US$) ✅CF | L2: IPM TOTAL (US$) ✅CF | M2: IGV UNIT. (US$) ✅CF | N2: IGV TOTAL (US$) ✅CF | O2: PERCEP. UNIT.(US$) ✅CF | P2: PERCEP. TOTAL.(US$) ✅CF | Q2: DEUDA ADUANERA UNIT. | R2: DEUDA ADUANERA TOTAL | S2: ADV UNIT. (S/.) | T2: ADV TOTAL. (S/.) | U2: IPM UNIT. (S/.) | V2: IPM TOTAL (S/.)2 | W2: IGV UNIT. (S/.) | X2: IGV TOTAL (S/.)2 | Y2: PERCEP. UNIT.(S/.) | Z2: PERCEP. TOTAL.(S/.)2 | AA2: TOTAL PAGO SUNAT UNIT.(US$) | AB2: TOTAL PAGO SUNAT TOTAL(US$) | AC2: TOTAL TRIB. UNIT.(S/.) | AD2: TOTAL TRIB. TOTAL .(S/.) | AE2: GASTOS IMP. UNIT.(US$) | AF2: GASTOS IMP. TOTAL.(US$)2 | AG2: GASTOS IMP. UNIT.(S/.) | AH2: GASTOS IMP. TOTAL.(S/.)2 | AI2: C/M UNIT. (US$) | AJ2: C/M UNIT. (S/.) | AK2: ADV UNIT. ⚠️COSTO (US$) | AL2: CF UNIT. ✅RECUP. (US$) | AM2: CF UNIT. ✅RECUP.(S/.) | AN2: CREDITO FISCAL POR PRODUCTO | AO2: MARGEN % | AP2: VALOR VTA. UNIT.(S/.) | AQ2: PRECIO VTA. c/IGV(S/.) | AR2: GANANCIA UNIT.(S/.) | AS2: PUNTO EQUILIBRIO | AT2: GANANCIA TOTAL(S/.) | AU2: % UTILIDAD S/PRECIO | AV2: ROI UNIT. | AW2: CLASIF. MARGEN
A3: ='🧾 Factura Comercial'!E5 -> Case Transparente TPU iPhone 15 | B3: ='🧾 Factura Comercial'!F5 -> Unid. | C3: ='🧾 Factura Comercial'!G5 -> 480 | D3: ='🧾 Factura Comercial'!H5 -> 1.21 | E3: ='🧾 Factura Comercial'!I5 -> 580.8 | F3: =IF('🧾 Tributos Aduana'!$F$6=0,0,'🧾 Factura Comercial'!I5/'🧾 Tributos Aduana'!$F$6) -> 0.040861813 | G3: ='🧾 Factura Comercial'!H5*'📋 Datos Generales'!$E$19 -> 4.5012 | H3: =TABLA_BASE[[#This Row],[FOB UNIT. (S/.)]]*TABLA_BASE[[#This Row],[CANTIDAD (unid.)]] -> 2160.576 | I3: =IF('🧾 Tributos Aduana'!$F$6=0,0,'🧾 Tributos Aduana'!$F$17*('🧾 Factura Comercial'!H5/'🧾 Tributos Aduana'!$F$6)) -> 0.083936974 | J3: =TABLA_BASE[[#This Row],[ADV UNIT. (US$) ⚠️COSTO]]*TABLA_BASE[[#This Row],[CANTIDAD (unid.)]] -> 40.289747 | K3: =IF('🧾 Tributos Aduana'!$F$6=0,0,'🧾 Tributos Aduana'!$F$18*('🧾 Factura Comercial'!H5/'🧾 Tributos Aduana'!$F$6)) -> 0.029624814 | L3: =TABLA_BASE[[#This Row],[IPM UNIT. (US$) ✅CF]]*TABLA_BASE[[#This Row],[CANTIDAD (unid.)]] -> 14.219911 | M3: =IF('🧾 Tributos Aduana'!$F$6=0,0,'🧾 Tributos Aduana'!$F$19*('🧾 Factura Comercial'!H5/'🧾 Tributos Aduana'!$F$6)) -> 0.23733903 | N3: =TABLA_BASE[[#This Row],[IGV UNIT. (US$) ✅CF]]*TABLA_BASE[[#This Row],[CANTIDAD (unid.)]] -> 113.92273 | O3: =IF('🧾 Tributos Aduana'!$F$6=0,0,'🧾 Tributos Aduana'!$F$23*('🧾 Factura Comercial'!H5/'🧾 Tributos Aduana'!$F$6)) -> 0.061258668 | P3: =TABLA_BASE[[#This Row],[PERCEP. UNIT.(US$) ✅CF]]*TABLA_BASE[[#This Row],[CANTIDAD (unid.)]] -> 29.40416 | Q3: =TABLA_BASE[[#This Row],[ADV UNIT. (US$) ⚠️COSTO]]+TABLA_BASE[[#This Row],[IPM UNIT. (US$) ✅CF]]+TABLA_BASE[[#This Row],[IGV UNIT. (US$) ✅CF]] -> 0.35090082 | R3: =TABLA_BASE[[#This Row],[DEUDA ADUANERA UNIT.]]*TABLA_BASE[[#This Row],[CANTIDAD (unid.)]] -> 168.43239 | S3: =TABLA_BASE[[#This Row],[ADV UNIT. (US$) ⚠️COSTO]]*'📋 Datos Generales'!$E$19 -> 0.31224554 | T3: =TABLA_BASE[[#This Row],[ADV UNIT. (S/.)]]*TABLA_BASE[[#This Row],[CANTIDAD (unid.)]] -> 149.87786 | U3: =TABLA_BASE[[#This Row],[IPM UNIT. (US$) ✅CF]]*'📋 Datos Generales'!$E$19 -> 0.11020431 | V3: =TABLA_BASE[[#This Row],[IPM UNIT. (S/.)]]*TABLA_BASE[[#This Row],[CANTIDAD (unid.)]] -> 52.898068 | W3: =TABLA_BASE[[#This Row],[IGV UNIT. (US$) ✅CF]]*'📋 Datos Generales'!$E$19 -> 0.88290119 | X3: =TABLA_BASE[[#This Row],[IGV UNIT. (S/.)]]*TABLA_BASE[[#This Row],[CANTIDAD (unid.)]] -> 423.79257 | Y3: =TABLA_BASE[[#This Row],[PERCEP. UNIT.(US$) ✅CF]]*'📋 Datos Generales'!$E$19 -> 0.22788224 | Z3: =TABLA_BASE[[#This Row],[PERCEP. UNIT.(S/.)]]*TABLA_BASE[[#This Row],[CANTIDAD (unid.)]] -> 109.38348 | AA3: =TABLA_BASE[[#This Row],[ADV UNIT. (US$) ⚠️COSTO]]+TABLA_BASE[[#This Row],[IPM UNIT. (US$) ✅CF]]+TABLA_BASE[[#This Row],[IGV UNIT. (US$) ✅CF]]+TABLA_BASE[[#This Row],[PERCEP. UNIT.(US$) ✅CF]] -> 0.41215948 | AB3: =TABLA_BASE[[#This Row],[TOTAL PAGO SUNAT UNIT.(US$)]]*TABLA_BASE[[#This Row],[CANTIDAD (unid.)]] -> 197.83655 | AC3: =TABLA_BASE[[#This Row],[TOTAL PAGO SUNAT UNIT.(US$)]]*'📋 Datos Generales'!$E$19 -> 1.5332333 | AD3: =TABLA_BASE[[#This Row],[TOTAL TRIB. UNIT.(S/.)]]*TABLA_BASE[[#This Row],[CANTIDAD (unid.)]] -> 735.95198 | AE3: =IF('🧾 Factura Comercial'!G5=0,0,'📦 Gastos Importación'!$E$28*(IF('🧾 Tributos Aduana'!$F$6=0,0,'🧾 Factura Comercial'!I5/'🧾 Tributos Aduana'!$F$6))/'🧾 Factura Comercial'!G5) -> 1.5824392 | AF3: =TABLA_BASE[[#This Row],[GASTOS IMP. UNIT.(US$)]]*TABLA_BASE[[#This Row],[CANTIDAD (unid.)]] -> 759.57084 | AG3: =TABLA_BASE[[#This Row],[GASTOS IMP. UNIT.(US$)]]*'📋 Datos Generales'!$E$19 -> 5.886674 | AH3: =TABLA_BASE[[#This Row],[GASTOS IMP. UNIT.(S/.)]]*TABLA_BASE[[#This Row],[CANTIDAD (unid.)]] -> 2825.6035 | AI3: ='🧮 Costos x Producto'!J7 -> 1.5824392 | AJ3: ='🧮 Costos x Producto'!K7 -> 5.886674 | AK3: =IF('🧾 Factura Comercial'!G5=0,0,'🧾 Tributos Aduana'!$F$17*(IF('🧾 Tributos Aduana'!$F$6=0,0,'🧾 Factura Comercial'!I5/'🧾 Tributos Aduana'!$F$6))/'🧾 Factura Comercial'!G5) -> 0.083936974 | AL3: =IF('🧾 Factura Comercial'!G5=0,0,'🏦 Crédito Fiscal'!$C$16*(IF('🧾 Tributos Aduana'!$F$6=0,0,'🧾 Factura Comercial'!I5/'🧾 Tributos Aduana'!$F$6))/'🧾 Factura Comercial'!G5) -> 0.34556084 | AM3: =TABLA_BASE[[#This Row],[CF UNIT. ✅RECUP. (US$)]]*'📋 Datos Generales'!$E$19 -> 1.2854863 | AN3: =TABLA_BASE[[#This Row],[CF UNIT. ✅RECUP.(S/.)]]*TABLA_BASE[[#This Row],[CANTIDAD (unid.)]] -> 617.03344 | AO3: ='💰 Precio de Venta'!G8 -> 0.4 | AP3: ='💰 Precio de Venta'!H8 -> 9.8111233 | AQ3: ='💰 Precio de Venta'!I8 -> 11.577126 | AR3: ='💰 Precio de Venta'!J8 -> 3.9244493 | AS3: ='💰 Precio de Venta'!K8 -> 66 | AT3: =TABLA_BASE[[#This Row],[GANANCIA UNIT.(S/.)]]*'🧾 Factura Comercial'!G5 -> 1883.7357 | AU3: =IF(TABLA_BASE[[#This Row],[PRECIO VTA. c/IGV(S/.)]]=0,0,TABLA_BASE[[#This Row],[GANANCIA UNIT.(S/.)]]/TABLA_BASE[[#This Row],[PRECIO VTA. c/IGV(S/.)]]) -> 0.33898305 | AV3: =IF(TABLA_BASE[[#This Row],[C/M UNIT. (S/.)]]=0,0,TABLA_BASE[[#This Row],[GANANCIA UNIT.(S/.)]]/TABLA_BASE[[#This Row],[C/M UNIT. (S/.)]]) -> 0.66666667 | AW3: =IF(TABLA_BASE[[#This Row],[MARGEN %]]>=0.5,"🟢 ALTO",IF(TABLA_BASE[[#This Row],[MARGEN %]]>=0.3,"🟡 MEDIO","🔴 BAJO")) -> 🟡 MEDIO
A4: ='🧾 Factura Comercial'!E6 -> Cable USB-C Trenzado 1m | B4: ='🧾 Factura Comercial'!F6 -> Unid. | C4: ='🧾 Factura Comercial'!G6 -> 2880 | D4: ='🧾 Factura Comercial'!H6 -> 0.68 | E4: ='🧾 Factura Comercial'!I6 -> 1958.4 | F4: =IF('🧾 Tributos Aduana'!$F$6=0,0,'🧾 Factura Comercial'!I6/'🧾 Tributos Aduana'!$F$6) -> 0.13778198 | G4: ='🧾 Factura Comercial'!H6*'📋 Datos Generales'!$E$19 -> 2.5296 | H4: =TABLA_BASE[[#This Row],[FOB UNIT. (S/.)]]*TABLA_BASE[[#This Row],[CANTIDAD (unid.)]] -> 7285.248 | I4: =IF('🧾 Tributos Aduana'!$F$6=0,0,'🧾 Tributos Aduana'!$F$17*('🧾 Factura Comercial'!H6/'🧾 Tributos Aduana'!$F$6)) -> 0.047171192 | J4: =TABLA_BASE[[#This Row],[ADV UNIT. (US$) ⚠️COSTO]]*TABLA_BASE[[#This Row],[CANTIDAD (unid.)]] -> 135.85303 | K4: =IF('🧾 Tributos Aduana'!$F$6=0,0,'🧾 Tributos Aduana'!$F$18*('🧾 Factura Comercial'!H6/'🧾 Tributos Aduana'!$F$6)) -> 0.016648656 | L4: =TABLA_BASE[[#This Row],[IPM UNIT. (US$) ✅CF]]*TABLA_BASE[[#This Row],[CANTIDAD (unid.)]] -> 47.948129 | M4: =IF('🧾 Tributos Aduana'!$F$6=0,0,'🧾 Tributos Aduana'!$F$19*('🧾 Factura Comercial'!H6/'🧾 Tributos Aduana'!$F$6)) -> 0.13338061 | N4: =TABLA_BASE[[#This Row],[IGV UNIT. (US$) ✅CF]]*TABLA_BASE[[#This Row],[CANTIDAD (unid.)]] -> 384.13616 | O4: =IF('🧾 Tributos Aduana'!$F$6=0,0,'🧾 Tributos Aduana'!$F$23*('🧾 Factura Comercial'!H6/'🧾 Tributos Aduana'!$F$6)) -> 0.034426359 | P4: =TABLA_BASE[[#This Row],[PERCEP. UNIT.(US$) ✅CF]]*TABLA_BASE[[#This Row],[CANTIDAD (unid.)]] -> 99.147913 | Q4: =TABLA_BASE[[#This Row],[ADV UNIT. (US$) ⚠️COSTO]]+TABLA_BASE[[#This Row],[IPM UNIT. (US$) ✅CF]]+TABLA_BASE[[#This Row],[IGV UNIT. (US$) ✅CF]] -> 0.19720046 | R4: =TABLA_BASE[[#This Row],[DEUDA ADUANERA UNIT.]]*TABLA_BASE[[#This Row],[CANTIDAD (unid.)]] -> 567.93732 | S4: =TABLA_BASE[[#This Row],[ADV UNIT. (US$) ⚠️COSTO]]*'📋 Datos Generales'!$E$19 -> 0.17547683 | T4: =TABLA_BASE[[#This Row],[ADV UNIT. (S/.)]]*TABLA_BASE[[#This Row],[CANTIDAD (unid.)]] -> 505.37328 | U4: =TABLA_BASE[[#This Row],[IPM UNIT. (US$) ✅CF]]*'📋 Datos Generales'!$E$19 -> 0.061933 | V4: =TABLA_BASE[[#This Row],[IPM UNIT. (S/.)]]*TABLA_BASE[[#This Row],[CANTIDAD (unid.)]] -> 178.36704 | W4: =TABLA_BASE[[#This Row],[IGV UNIT. (US$) ✅CF]]*'📋 Datos Generales'!$E$19 -> 0.49617587 | X4: =TABLA_BASE[[#This Row],[IGV UNIT. (S/.)]]*TABLA_BASE[[#This Row],[CANTIDAD (unid.)]] -> 1428.9865 | Y4: =TABLA_BASE[[#This Row],[PERCEP. UNIT.(US$) ✅CF]]*'📋 Datos Generales'!$E$19 -> 0.12806605 | Z4: =TABLA_BASE[[#This Row],[PERCEP. UNIT.(S/.)]]*TABLA_BASE[[#This Row],[CANTIDAD (unid.)]] -> 368.83024 | AA4: =TABLA_BASE[[#This Row],[ADV UNIT. (US$) ⚠️COSTO]]+TABLA_BASE[[#This Row],[IPM UNIT. (US$) ✅CF]]+TABLA_BASE[[#This Row],[IGV UNIT. (US$) ✅CF]]+TABLA_BASE[[#This Row],[PERCEP. UNIT.(US$) ✅CF]] -> 0.23162682 | AB4: =TABLA_BASE[[#This Row],[TOTAL PAGO SUNAT UNIT.(US$)]]*TABLA_BASE[[#This Row],[CANTIDAD (unid.)]] -> 667.08524 | AC4: =TABLA_BASE[[#This Row],[TOTAL PAGO SUNAT UNIT.(US$)]]*'📋 Datos Generales'!$E$19 -> 0.86165176 | AD4: =TABLA_BASE[[#This Row],[TOTAL TRIB. UNIT.(S/.)]]*TABLA_BASE[[#This Row],[CANTIDAD (unid.)]] -> 2481.5571 | AE4: =IF('🧾 Factura Comercial'!G6=0,0,'📦 Gastos Importación'!$E$28*(IF('🧾 Tributos Aduana'!$F$6=0,0,'🧾 Factura Comercial'!I6/'🧾 Tributos Aduana'!$F$6))/'🧾 Factura Comercial'!G6) -> 0.8893047 | AF4: =TABLA_BASE[[#This Row],[GASTOS IMP. UNIT.(US$)]]*TABLA_BASE[[#This Row],[CANTIDAD (unid.)]] -> 2561.1975 | AG4: =TABLA_BASE[[#This Row],[GASTOS IMP. UNIT.(US$)]]*'📋 Datos Generales'!$E$19 -> 3.3082135 | AH4: =TABLA_BASE[[#This Row],[GASTOS IMP. UNIT.(S/.)]]*TABLA_BASE[[#This Row],[CANTIDAD (unid.)]] -> 9527.6549 | AI4: ='🧮 Costos x Producto'!J8 -> 0.8893047 | AJ4: ='🧮 Costos x Producto'!K8 -> 3.3082135 | AK4: =IF('🧾 Factura Comercial'!G6=0,0,'🧾 Tributos Aduana'!$F$17*(IF('🧾 Tributos Aduana'!$F$6=0,0,'🧾 Factura Comercial'!I6/'🧾 Tributos Aduana'!$F$6))/'🧾 Factura Comercial'!G6) -> 0.047171192 | AL4: =IF('🧾 Factura Comercial'!G6=0,0,'🏦 Crédito Fiscal'!$C$16*(IF('🧾 Tributos Aduana'!$F$6=0,0,'🧾 Factura Comercial'!I6/'🧾 Tributos Aduana'!$F$6))/'🧾 Factura Comercial'!G6) -> 0.19419948 | AM4: =TABLA_BASE[[#This Row],[CF UNIT. ✅RECUP. (US$)]]*'📋 Datos Generales'!$E$19 -> 0.72242207 | AN4: =TABLA_BASE[[#This Row],[CF UNIT. ✅RECUP.(S/.)]]*TABLA_BASE[[#This Row],[CANTIDAD (unid.)]] -> 2080.5756 | AO4: ='💰 Precio de Venta'!G9 -> 0.4 | AP4: ='💰 Precio de Venta'!H9 -> 5.5136892 | AQ4: ='💰 Precio de Venta'!I9 -> 6.5061532 | AR4: ='💰 Precio de Venta'!J9 -> 2.2054757 | AS4: ='💰 Precio de Venta'!K9 -> 394 | AT4: =TABLA_BASE[[#This Row],[GANANCIA UNIT.(S/.)]]*'🧾 Factura Comercial'!G6 -> 6351.7699 | AU4: =IF(TABLA_BASE[[#This Row],[PRECIO VTA. c/IGV(S/.)]]=0,0,TABLA_BASE[[#This Row],[GANANCIA UNIT.(S/.)]]/TABLA_BASE[[#This Row],[PRECIO VTA. c/IGV(S/.)]]) -> 0.33898305 | AV4: =IF(TABLA_BASE[[#This Row],[C/M UNIT. (S/.)]]=0,0,TABLA_BASE[[#This Row],[GANANCIA UNIT.(S/.)]]/TABLA_BASE[[#This Row],[C/M UNIT. (S/.)]]) -> 0.66666667 | AW4: =IF(TABLA_BASE[[#This Row],[MARGEN %]]>=0.5,"🟢 ALTO",IF(TABLA_BASE[[#This Row],[MARGEN %]]>=0.3,"🟡 MEDIO","🔴 BAJO")) -> 🟡 MEDIO
A5: ='🧾 Factura Comercial'!E7 -> Protector Pantalla Vidrio Templado | B5: ='🧾 Factura Comercial'!F7 -> Unid. | C5: ='🧾 Factura Comercial'!G7 -> 2880 | D5: ='🧾 Factura Comercial'!H7 -> 0.4 | E5: ='🧾 Factura Comercial'!I7 -> 1152 | F5: =IF('🧾 Tributos Aduana'!$F$6=0,0,'🧾 Factura Comercial'!I7/'🧾 Tributos Aduana'!$F$6) -> 0.081048224 | G5: ='🧾 Factura Comercial'!H7*'📋 Datos Generales'!$E$19 -> 1.488 | H5: =TABLA_BASE[[#This Row],[FOB UNIT. (S/.)]]*TABLA_BASE[[#This Row],[CANTIDAD (unid.)]] -> 4285.44 | I5: =IF('🧾 Tributos Aduana'!$F$6=0,0,'🧾 Tributos Aduana'!$F$17*('🧾 Factura Comercial'!H7/'🧾 Tributos Aduana'!$F$6)) -> 0.02774776 | J5: =TABLA_BASE[[#This Row],[ADV UNIT. (US$) ⚠️COSTO]]*TABLA_BASE[[#This Row],[CANTIDAD (unid.)]] -> 79.913549 | K5: =IF('🧾 Tributos Aduana'!$F$6=0,0,'🧾 Tributos Aduana'!$F$18*('🧾 Factura Comercial'!H7/'🧾 Tributos Aduana'!$F$6)) -> 0.009793327 | L5: =TABLA_BASE[[#This Row],[IPM UNIT. (US$) ✅CF]]*TABLA_BASE[[#This Row],[CANTIDAD (unid.)]] -> 28.204782 | M5: =IF('🧾 Tributos Aduana'!$F$6=0,0,'🧾 Tributos Aduana'!$F$19*('🧾 Factura Comercial'!H7/'🧾 Tributos Aduana'!$F$6)) -> 0.078459183 | N5: =TABLA_BASE[[#This Row],[IGV UNIT. (US$) ✅CF]]*TABLA_BASE[[#This Row],[CANTIDAD (unid.)]] -> 225.96245 | O5: =IF('🧾 Tributos Aduana'!$F$6=0,0,'🧾 Tributos Aduana'!$F$23*('🧾 Factura Comercial'!H7/'🧾 Tributos Aduana'!$F$6)) -> 0.020250799 | P5: =TABLA_BASE[[#This Row],[PERCEP. UNIT.(US$) ✅CF]]*TABLA_BASE[[#This Row],[CANTIDAD (unid.)]] -> 58.322302 | Q5: =TABLA_BASE[[#This Row],[ADV UNIT. (US$) ⚠️COSTO]]+TABLA_BASE[[#This Row],[IPM UNIT. (US$) ✅CF]]+TABLA_BASE[[#This Row],[IGV UNIT. (US$) ✅CF]] -> 0.11600027 | R5: =TABLA_BASE[[#This Row],[DEUDA ADUANERA UNIT.]]*TABLA_BASE[[#This Row],[CANTIDAD (unid.)]] -> 334.08078 | S5: =TABLA_BASE[[#This Row],[ADV UNIT. (US$) ⚠️COSTO]]*'📋 Datos Generales'!$E$19 -> 0.10322167 | T5: =TABLA_BASE[[#This Row],[ADV UNIT. (S/.)]]*TABLA_BASE[[#This Row],[CANTIDAD (unid.)]] -> 297.2784 | U5: =TABLA_BASE[[#This Row],[IPM UNIT. (US$) ✅CF]]*'📋 Datos Generales'!$E$19 -> 0.036431177 | V5: =TABLA_BASE[[#This Row],[IPM UNIT. (S/.)]]*TABLA_BASE[[#This Row],[CANTIDAD (unid.)]] -> 104.92179 | W5: =TABLA_BASE[[#This Row],[IGV UNIT. (US$) ✅CF]]*'📋 Datos Generales'!$E$19 -> 0.29186816 | X5: =TABLA_BASE[[#This Row],[IGV UNIT. (S/.)]]*TABLA_BASE[[#This Row],[CANTIDAD (unid.)]] -> 840.58031 | Y5: =TABLA_BASE[[#This Row],[PERCEP. UNIT.(US$) ✅CF]]*'📋 Datos Generales'!$E$19 -> 0.075332973 | Z5: =TABLA_BASE[[#This Row],[PERCEP. UNIT.(S/.)]]*TABLA_BASE[[#This Row],[CANTIDAD (unid.)]] -> 216.95896 | AA5: =TABLA_BASE[[#This Row],[ADV UNIT. (US$) ⚠️COSTO]]+TABLA_BASE[[#This Row],[IPM UNIT. (US$) ✅CF]]+TABLA_BASE[[#This Row],[IGV UNIT. (US$) ✅CF]]+TABLA_BASE[[#This Row],[PERCEP. UNIT.(US$) ✅CF]] -> 0.13625107 | AB5: =TABLA_BASE[[#This Row],[TOTAL PAGO SUNAT UNIT.(US$)]]*TABLA_BASE[[#This Row],[CANTIDAD (unid.)]] -> 392.40308 | AC5: =TABLA_BASE[[#This Row],[TOTAL PAGO SUNAT UNIT.(US$)]]*'📋 Datos Generales'!$E$19 -> 0.50685398 | AD5: =TABLA_BASE[[#This Row],[TOTAL TRIB. UNIT.(S/.)]]*TABLA_BASE[[#This Row],[CANTIDAD (unid.)]] -> 1459.7395 | AE5: =IF('🧾 Factura Comercial'!G7=0,0,'📦 Gastos Importación'!$E$28*(IF('🧾 Tributos Aduana'!$F$6=0,0,'🧾 Factura Comercial'!I7/'🧾 Tributos Aduana'!$F$6))/'🧾 Factura Comercial'!G7) -> 0.52312041 | AF5: =TABLA_BASE[[#This Row],[GASTOS IMP. UNIT.(US$)]]*TABLA_BASE[[#This Row],[CANTIDAD (unid.)]] -> 1506.5868 | AG5: =TABLA_BASE[[#This Row],[GASTOS IMP. UNIT.(US$)]]*'📋 Datos Generales'!$E$19 -> 1.9460079 | AH5: =TABLA_BASE[[#This Row],[GASTOS IMP. UNIT.(S/.)]]*TABLA_BASE[[#This Row],[CANTIDAD (unid.)]] -> 5604.5029 | AI5: ='🧮 Costos x Producto'!J9 -> 0.52312041 | AJ5: ='🧮 Costos x Producto'!K9 -> 1.9460079 | AK5: =IF('🧾 Factura Comercial'!G7=0,0,'🧾 Tributos Aduana'!$F$17*(IF('🧾 Tributos Aduana'!$F$6=0,0,'🧾 Factura Comercial'!I7/'🧾 Tributos Aduana'!$F$6))/'🧾 Factura Comercial'!G7) -> 0.02774776 | AL5: =IF('🧾 Factura Comercial'!G7=0,0,'🏦 Crédito Fiscal'!$C$16*(IF('🧾 Tributos Aduana'!$F$6=0,0,'🧾 Factura Comercial'!I7/'🧾 Tributos Aduana'!$F$6))/'🧾 Factura Comercial'!G7) -> 0.11423499 | AM5: =TABLA_BASE[[#This Row],[CF UNIT. ✅RECUP. (US$)]]*'📋 Datos Generales'!$E$19 -> 0.42495416 | AN5: =TABLA_BASE[[#This Row],[CF UNIT. ✅RECUP.(S/.)]]*TABLA_BASE[[#This Row],[CANTIDAD (unid.)]] -> 1223.868 | AO5: ='💰 Precio de Venta'!G10 -> 0.4 | AP5: ='💰 Precio de Venta'!H10 -> 3.2433466 | AQ5: ='💰 Precio de Venta'!I10 -> 3.8271489 | AR5: ='💰 Precio de Venta'!J10 -> 1.2973386 | AS5: ='💰 Precio de Venta'!K10 -> 394 | AT5: =TABLA_BASE[[#This Row],[GANANCIA UNIT.(S/.)]]*'🧾 Factura Comercial'!G7 -> 3736.3352 | AU5: =IF(TABLA_BASE[[#This Row],[PRECIO VTA. c/IGV(S/.)]]=0,0,TABLA_BASE[[#This Row],[GANANCIA UNIT.(S/.)]]/TABLA_BASE[[#This Row],[PRECIO VTA. c/IGV(S/.)]]) -> 0.33898305 | AV5: =IF(TABLA_BASE[[#This Row],[C/M UNIT. (S/.)]]=0,0,TABLA_BASE[[#This Row],[GANANCIA UNIT.(S/.)]]/TABLA_BASE[[#This Row],[C/M UNIT. (S/.)]]) -> 0.66666667 | AW5: =IF(TABLA_BASE[[#This Row],[MARGEN %]]>=0.5,"🟢 ALTO",IF(TABLA_BASE[[#This Row],[MARGEN %]]>=0.3,"🟡 MEDIO","🔴 BAJO")) -> 🟡 MEDIO
A6: ='🧾 Factura Comercial'!E8 -> Audífonos In-Ear con Micrófono | B6: ='🧾 Factura Comercial'!F8 -> Unid. | C6: ='🧾 Factura Comercial'!G8 -> 10224 | D6: ='🧾 Factura Comercial'!H8 -> 0.34 | E6: ='🧾 Factura Comercial'!I8 -> 3476.16 | F6: =IF('🧾 Tributos Aduana'!$F$6=0,0,'🧾 Factura Comercial'!I8/'🧾 Tributos Aduana'!$F$6) -> 0.24456301 | G6: ='🧾 Factura Comercial'!H8*'📋 Datos Generales'!$E$19 -> 1.2648 | H6: =TABLA_BASE[[#This Row],[FOB UNIT. (S/.)]]*TABLA_BASE[[#This Row],[CANTIDAD (unid.)]] -> 12931.315 | I6: =IF('🧾 Tributos Aduana'!$F$6=0,0,'🧾 Tributos Aduana'!$F$17*('🧾 Factura Comercial'!H8/'🧾 Tributos Aduana'!$F$6)) -> 0.023585596 | J6: =TABLA_BASE[[#This Row],[ADV UNIT. (US$) ⚠️COSTO]]*TABLA_BASE[[#This Row],[CANTIDAD (unid.)]] -> 241.13913 | K6: =IF('🧾 Tributos Aduana'!$F$6=0,0,'🧾 Tributos Aduana'!$F$18*('🧾 Factura Comercial'!H8/'🧾 Tributos Aduana'!$F$6)) -> 0.008324328 | L6: =TABLA_BASE[[#This Row],[IPM UNIT. (US$) ✅CF]]*TABLA_BASE[[#This Row],[CANTIDAD (unid.)]] -> 85.107929 | M6: =IF('🧾 Tributos Aduana'!$F$6=0,0,'🧾 Tributos Aduana'!$F$19*('🧾 Factura Comercial'!H8/'🧾 Tributos Aduana'!$F$6)) -> 0.066690306 | N6: =TABLA_BASE[[#This Row],[IGV UNIT. (US$) ✅CF]]*TABLA_BASE[[#This Row],[CANTIDAD (unid.)]] -> 681.84169 | O6: =IF('🧾 Tributos Aduana'!$F$6=0,0,'🧾 Tributos Aduana'!$F$23*('🧾 Factura Comercial'!H8/'🧾 Tributos Aduana'!$F$6)) -> 0.017213179 | P6: =TABLA_BASE[[#This Row],[PERCEP. UNIT.(US$) ✅CF]]*TABLA_BASE[[#This Row],[CANTIDAD (unid.)]] -> 175.98755 | Q6: =TABLA_BASE[[#This Row],[ADV UNIT. (US$) ⚠️COSTO]]+TABLA_BASE[[#This Row],[IPM UNIT. (US$) ✅CF]]+TABLA_BASE[[#This Row],[IGV UNIT. (US$) ✅CF]] -> 0.09860023 | R6: =TABLA_BASE[[#This Row],[DEUDA ADUANERA UNIT.]]*TABLA_BASE[[#This Row],[CANTIDAD (unid.)]] -> 1008.0887 | S6: =TABLA_BASE[[#This Row],[ADV UNIT. (US$) ⚠️COSTO]]*'📋 Datos Generales'!$E$19 -> 0.087738417 | T6: =TABLA_BASE[[#This Row],[ADV UNIT. (S/.)]]*TABLA_BASE[[#This Row],[CANTIDAD (unid.)]] -> 897.03757 | U6: =TABLA_BASE[[#This Row],[IPM UNIT. (US$) ✅CF]]*'📋 Datos Generales'!$E$19 -> 0.0309665 | V6: =TABLA_BASE[[#This Row],[IPM UNIT. (S/.)]]*TABLA_BASE[[#This Row],[CANTIDAD (unid.)]] -> 316.6015 | W6: =TABLA_BASE[[#This Row],[IGV UNIT. (US$) ✅CF]]*'📋 Datos Generales'!$E$19 -> 0.24808794 | X6: =TABLA_BASE[[#This Row],[IGV UNIT. (S/.)]]*TABLA_BASE[[#This Row],[CANTIDAD (unid.)]] -> 2536.4511 | Y6: =TABLA_BASE[[#This Row],[PERCEP. UNIT.(US$) ✅CF]]*'📋 Datos Generales'!$E$19 -> 0.064033027 | Z6: =TABLA_BASE[[#This Row],[PERCEP. UNIT.(S/.)]]*TABLA_BASE[[#This Row],[CANTIDAD (unid.)]] -> 654.67367 | AA6: =TABLA_BASE[[#This Row],[ADV UNIT. (US$) ⚠️COSTO]]+TABLA_BASE[[#This Row],[IPM UNIT. (US$) ✅CF]]+TABLA_BASE[[#This Row],[IGV UNIT. (US$) ✅CF]]+TABLA_BASE[[#This Row],[PERCEP. UNIT.(US$) ✅CF]] -> 0.11581341 | AB6: =TABLA_BASE[[#This Row],[TOTAL PAGO SUNAT UNIT.(US$)]]*TABLA_BASE[[#This Row],[CANTIDAD (unid.)]] -> 1184.0763 | AC6: =TABLA_BASE[[#This Row],[TOTAL PAGO SUNAT UNIT.(US$)]]*'📋 Datos Generales'!$E$19 -> 0.43082588 | AD6: =TABLA_BASE[[#This Row],[TOTAL TRIB. UNIT.(S/.)]]*TABLA_BASE[[#This Row],[CANTIDAD (unid.)]] -> 4404.7638 | AE6: =IF('🧾 Factura Comercial'!G8=0,0,'📦 Gastos Importación'!$E$28*(IF('🧾 Tributos Aduana'!$F$6=0,0,'🧾 Factura Comercial'!I8/'🧾 Tributos Aduana'!$F$6))/'🧾 Factura Comercial'!G8) -> 0.44465235 | AF6: =TABLA_BASE[[#This Row],[GASTOS IMP. UNIT.(US$)]]*TABLA_BASE[[#This Row],[CANTIDAD (unid.)]] -> 4546.1256 | AG6: =TABLA_BASE[[#This Row],[GASTOS IMP. UNIT.(US$)]]*'📋 Datos Generales'!$E$19 -> 1.6541067 | AH6: =TABLA_BASE[[#This Row],[GASTOS IMP. UNIT.(S/.)]]*TABLA_BASE[[#This Row],[CANTIDAD (unid.)]] -> 16911.587 | AI6: ='🧮 Costos x Producto'!J10 -> 0.44465235 | AJ6: ='🧮 Costos x Producto'!K10 -> 1.6541067 | AK6: =IF('🧾 Factura Comercial'!G8=0,0,'🧾 Tributos Aduana'!$F$17*(IF('🧾 Tributos Aduana'!$F$6=0,0,'🧾 Factura Comercial'!I8/'🧾 Tributos Aduana'!$F$6))/'🧾 Factura Comercial'!G8) -> 0.023585596 | AL6: =IF('🧾 Factura Comercial'!G8=0,0,'🏦 Crédito Fiscal'!$C$16*(IF('🧾 Tributos Aduana'!$F$6=0,0,'🧾 Factura Comercial'!I8/'🧾 Tributos Aduana'!$F$6))/'🧾 Factura Comercial'!G8) -> 0.097099741 | AM6: =TABLA_BASE[[#This Row],[CF UNIT. ✅RECUP. (US$)]]*'📋 Datos Generales'!$E$19 -> 0.36121104 | AN6: =TABLA_BASE[[#This Row],[CF UNIT. ✅RECUP.(S/.)]]*TABLA_BASE[[#This Row],[CANTIDAD (unid.)]] -> 3693.0216 | AO6: ='💰 Precio de Venta'!G11 -> 0.4 | AP6: ='💰 Precio de Venta'!H11 -> 2.7568446 | AQ6: ='💰 Precio de Venta'!I11 -> 3.2530766 | AR6: ='💰 Precio de Venta'!J11 -> 1.1027378 | AS6: ='💰 Precio de Venta'!K11 -> 1398 | AT6: =TABLA_BASE[[#This Row],[GANANCIA UNIT.(S/.)]]*'🧾 Factura Comercial'!G8 -> 11274.392 | AU6: =IF(TABLA_BASE[[#This Row],[PRECIO VTA. c/IGV(S/.)]]=0,0,TABLA_BASE[[#This Row],[GANANCIA UNIT.(S/.)]]/TABLA_BASE[[#This Row],[PRECIO VTA. c/IGV(S/.)]]) -> 0.33898305 | AV6: =IF(TABLA_BASE[[#This Row],[C/M UNIT. (S/.)]]=0,0,TABLA_BASE[[#This Row],[GANANCIA UNIT.(S/.)]]/TABLA_BASE[[#This Row],[C/M UNIT. (S/.)]]) -> 0.66666667 | AW6: =IF(TABLA_BASE[[#This Row],[MARGEN %]]>=0.5,"🟢 ALTO",IF(TABLA_BASE[[#This Row],[MARGEN %]]>=0.3,"🟡 MEDIO","🔴 BAJO")) -> 🟡 MEDIO
