Workbook

Sheet 🏠 PORTADA
E2: 🌎 CALCULADORA PROFESIONAL DE COSTOS DE IMPORTACIÓN
E3: P E R Ú — S I S T E M A D E G E S T I Ó N A D U A N E R A
E6: La herramienta definitiva para calcular costos, tributos y precios de importación en el Perú
E8: ✦ ¿QUÉ INCLUYE ESTA HERRAMIENTA? ✦
E9: 📋 DATOS GENERALES | G9: Registro completo del DUA, importador, Incoterm y parámetros tributarios configurables
E10: 🧾 FACTURA COMERCIAL | G10: Ingreso de hasta 30+ productos con cálculo automático de FOB total y prorrateo unitario
E11: 📦 GASTOS DE IMPORTACIÓN | G11: 21 conceptos pre-cargados: handling, tracción, almacenaje, agente, transporte y más
E12: ⚖️ TRIBUTOS ADUANEROS | G12: Cálculo automático: CIF, ADV, IPM, IGV, Deuda Aduanera y Percepción según SUNAT
E13: 🧮 COSTOS POR PRODUCTO | G13: Factor de prorrateo (6 dígitos) y costo unitario en USD y S/. para cada producto
E14: 💰 PRECIO DE VENTA | G14: Margen global o por producto. VV = CT/(1-Margen%). Punto de equilibrio automático
E15: 🏦 CRÉDITO FISCAL | G15: Detalle completo: IGV, IPM, Percepción y gastos afectos. Valor total recuperable en S/.
E16: 📊 DASHBOARD EJECUTIVO | G16: 8+ gráficos dinámicos: costos, tributos, márgenes, rentabilidad por producto y más
E18: ✦ FLUJO DE TRABAJO — 8 PASOS SIMPLES ✦
E19: PASO 1 Configura | F19: PASO 2 Carga | G19: PASO 3 Registra | H19: PASO 4 Automático | I19: PASO 5 Analiza | J19: PASO 6 Define | K19: PASO 7 Recupera | L19: PASO 8 Decide
E20: Datos generales, tipo de cambio y parámetros tributarios | F20: Productos de la factura comercial con FOB unitario | G20: Gastos de importación pagados a operadores y agentes | H20: El sistema calcula CIF, tributos y deuda aduanera | I20: Revisa el costo unitario y factor de prorrateo | J20: Establece tu margen y obtén precios de venta sugeridos | K20: Visualiza tu crédito fiscal total a recuperar | L20: Revisa el dashboard con todos los KPIs y gráficos
E22: ✦ LEYENDA DE COLORES ✦
E23: 🟡 AMARILLO Campo editable — ingresa tus datos aquí | G23: 🟢 VERDE Calculado automáticamente — no editar | I23: 🔵 AZUL Total o resumen principal de la sección | K23: 🟠 NARANJA Precio de venta o margen de ganancia
E25: ⚠️ IMPORTANTE: Actualice el Tipo de Cambio antes de cada operación | Verifique el Ad Valorem con su Agente de Aduanas
E26: 📧 Herramienta desarrollada para uso profesional en comercio exterior peruano Elaborado por : Rosalinda Jiménez Espinoza By Sally Control Tower Con Derechos de Autoria | J26: Versión 2.0 | 2026

Sheet 📖 Instrucciones
A1: 📖 GUÍA COMPLETA DE USO — CALCULADORA DE COSTOS DE IMPORTACIÓN PERÚ
D3: PASO 1 — 📋 DATOS GENERALES
D4: → Complete todos los datos en color AMARILLO: DUA, razón social, RUC, fecha, país, proveedor, incoterm, canal. | F4: "📌 NOTA IMPORTANTE — USO DE LA PLANTILLA Esta calculadora está diseñada para ser usada por operación de importación. Si realizas varias importaciones, te recomendamos seguir este flujo de trabajo: 1️⃣ Completa esta plantilla con los datos de tu importación actual. 2️⃣ Guarda el archivo con un nombre que identifique la operación — por ejemplo: Importación_Enero2026_China o DAM-2026-000001. 3️⃣ Para tu próxima importación, abre el archivo original, haz una copia y renómbrala. De esta forma tendrás un historial ordenado de cada importación, con todos sus costos, tributos y márgenes guardados por separado. ✅ Así podrás comparar operaciones, identificar en cuál ganaste más y tomar mejores decisiones en cada nueva importación."
D5: → IMPORTANTE: Actualice el Tipo de Cambio USD→PEN antes de cada operación (fuente: SUNAT / BCR).
D6: → Configure los parámetros tributarios: Ad Valorem según partida arancelaria (0%, 6% u 11%), percepción según tipo de importador.
D7: → Tasas de percepción: 10% = primera importación / empresa nueva | 3.5% = producto nuevo importador frecuente | 5% = producto de segundo uso.
D9: PASO 2 — 🧾 FACTURA COMERCIAL
D10: → Ingrese cada producto: descripción, unidad de medida, cantidad total y precio FOB unitario en USD.
D11: → El sistema calcula automáticamente el FOB Total, el Factor de Prorrateo y el Costo Unitario.
D12: → Puede manejar hasta 30 productos diferentes en una misma importación.
D14: PASO 3 — 📦 GASTOS DE IMPORTACIÓN
D15: → Ingrese el monto de cada gasto pagado a los operadores: handling, descarga, tracción, almacenaje, transporte, etc.
D16: → Los gastos marcados ⭐ son afectos a IGV (18%) y generan crédito fiscal.
D17: → El Derecho de Emisión del Seguro y la Comisión del Agente se calculan automáticamente.
D18: → Complete también los gastos administrativos y financieros (transferencias, intereses de letras, carta de crédito).
... D49: ⚠️ Esta plantilla es una herramienta de estimación profesional — consulte siempre a un agente de aduanas certificado.

Sheet Doc. Necesarios
B2: DOCUMENTOS QUE DEBES DE TENER A LA MANO PARA LLENAR LA PLANTILLA
B4: 1 | C4: Proforma Comercial y/o Factura Invoice
B5: 2 | C5: Proforma o Liquidación del Agente de Aduana
C6: 2.1 | D6: Derechos de Aduana
C7: 2.2 | D7: Flete Internacional
C8: 2.3 | D8: Comisión del Agente
C9: 2.4 | D9: Gastos de Nacionalizacion
C10: 2.5 | D10: Transporte Interno

Sheet 📋 Datos Generales
D1: 📋 CALCULADORA DE COSTOS DE IMPORTACIÓN — PERÚ
D2: Complete los datos en AMARILLO 🟡. Los campos en VERDE 🟢 se calculan automáticamente.
D4: 📄 DATOS DE LA OPERACIÓN DE IMPORTACIÓN
D5: Número de DUA / DAM | E5: DAM-2025-000001
D6: Razón Social del Importador | E6: EMPRESA IMPORTADORA S.A.C.
D7: RUC del Importador | E7: 20XXXXXXXXX
D8: Fecha de Numeración DAM | E8: 24/02/2026
D9: País de Origen | E9: China
D10: Proveedor / Exportador | E10: HWPI Co. Ltd.
D11: Incoterm | E11: FOB
D12: Vía de Transporte | E12: Marítima
D13: Puerto de Embarque | E13: Shekou, China
D14: Puerto de Destino | E14: Callao, Perú
D15: Agente de Aduanas | E15: Agencia SAC
D16: Canal de Control | E16: Naranja
D18: ⚖️ PARÁMETROS TRIBUTARIOS (Configuración)
D19: Tipo de Cambio USD → PEN | E19: 3.72 | F19: Actualizar según SUNAT / BCR
D20: Ad Valorem — Arancel (%) | E20: 0.06 | F20: 0%, 6% u 11% según partida arancelaria
D21: IGV (%) | E21: 0.16 | F21: Fijo 16%
D22: IPM (%) | E22: 0.02 | F22: Fijo 2%
D23: Percepción IGV (%) | E23: 0.035 | F23: 10% nueva empresa / 3.5% producto nuevo / 5% segundo uso
D24: Prima Neta Seguro (%) | E24: 0 | F24: % sobre la Suma Asegurada
D25: Derecho de Emisión Seguro (%) | E25: 0 | F25: 3% sobre Prima Neta — negociable
D26: Deducible Seguro (%) | E26: 0 | F26: % del que somos responsables en siniestro
D27: Comisión Agente Aduanas (%) | E27: 0.01 | F27: % sobre CIF (mín. S/. 100)
D28: IGV Servicios (%) | E28: 0.18 | F28: 18% (IGV 16% + IPM 2%)
D30: 🟡 Amarillo = Dato editable 🟢 Verde = Calculado automáticamente 🔵 Azul = Total general

Sheet 🧾 Factura Comercial
E2: MONTO TOTAL FOB USD | F2: =I507 -> 43641.28
D4: 🧾 FACTURA COMERCIAL — DETALLE DE PRODUCTOS
D5: Ingrese cada producto: descripción, unidad, cantidad y precio FOB unitario (USD).
D6: # | E6: DESCRIPCIÓN DEL PRODUCTO | F6: UNIDAD MEDIDA | G6: CANTIDAD (unid.) | H6: FOB UNIT. (USD) | I6: FOB TOTAL (USD) | J6: PARTICIPACIÓN | K6: COSTO UNIT. (PEN) | L6: PRECIO VENTA (PEN)
D7: 1 | E7: Case Transparente TPU iPhone 15 | F7: Unid. | G7: 480 | H7: 1.21 | I7: =IF(G7=0,0,G7*H7) -> 580.8 | J7: =IF(I7=0,0,I7/$I$507) -> 0.013308501 | K7: ='🧮 Costos x Producto'!K7 -> 5.1345892 | L7: ='💰 Precio de Venta'!H8 -> 8.5576486
D8: 2 | E8: Cable USB-C Trenzado 1m | F8: Unid. | G8: 2880 | H8: 0.68 | I8: =IF(G8=0,0,G8*H8) -> 1958.4 | J8: =IF(I8=0,0,I8/$I$507) -> 0.044874944 | K8: ='🧮 Costos x Producto'!K8 -> 2.8855542 | L8: ='💰 Precio de Venta'!H9 -> 4.8092571
D9: 3 | E9: Protector Pantalla Vidrio Templado | F9: Unid. | G9: 2880 | H9: 0.4 | I9: =IF(G9=0,0,G9*H9) -> 1152 | J9: =IF(I9=0,0,I9/$I$507) -> 0.026397026 | K9: ='🧮 Costos x Producto'!K9 -> 1.6973849 | L9: ='💰 Precio de Venta'!H10 -> 2.8289748
D10: 4 | E10: Audífonos In-Ear con Micrófono | F10: Unid. | G10: 10224 | H10: 0.34 | I10: =IF(G10=0,0,G10*H10) -> 3476.16 | J10: =IF(I10=0,0,I10/$I$507) -> 0.079653026 | K10: ='🧮 Costos x Producto'!K10 -> 1.4427771 | L10: ='💰 Precio de Venta'!H11 -> 2.4046285
D11: 5 | E11: Cable Micro USB 2m Nylon | F11: Unid. | G11: 8640 | H11: 0.26 | I11: =IF(G11=0,0,G11*H11) -> 2246.4 | J11: =IF(I11=0,0,I11/$I$507) -> 0.051474201 | K11: ='🧮 Costos x Producto'!K11 -> 1.1033002 | L11: ='💰 Precio de Venta'!H12 -> 1.8388336
D12: 6 | E12: Soporte Anillo Pop Socket Metálico | F12: Unid. | G12: 2160 | H12: 0.29 | I12: =IF(G12=0,0,G12*H12) -> 626.4 | J12: =IF(I12=0,0,I12/$I$507) -> 0.014353383 | K12: ='🧮 Costos x Producto'!K12 -> 1.230604 | L12: ='💰 Precio de Venta'!H13 -> 2.0510067
D13: 7 | E13: Cargador Inalámbrico 15W Qi | F13: Unid. | G13: 240 | H13: 5.71 | I13: =IF(G13=0,0,G13*H13) -> 1370.4 | J13: =IF(I13=0,0,I13/$I$507) -> 0.031401462 | K13: ='🧮 Costos x Producto'!K13 -> 24.230169 | L13: ='💰 Precio de Venta'!H14 -> 40.383615
D14: 8 | E14: Case Wallet Cuero PU Samsung S24 | F14: Unid. | G14: 1920 | H14: 0.76 | I14: =IF(G14=0,0,G14*H14) -> 1459.2 | J14: =IF(I14=0,0,I14/$I$507) -> 0.033436233 | K14: ='🧮 Costos x Producto'!K14 -> 3.2250312 | L14: ='💰 Precio de Venta'!H15 -> 5.375052
D15: 9 | E15: Adaptador USB-C a Jack 3.5mm | F15: Unid. | G15: 4800 | H15: 0.28 | I15: =IF(G15=0,0,G15*H15) -> 1344 | J15: =IF(I15=0,0,I15/$I$507) -> 0.03079653 | K15: ='🧮 Costos x Producto'!K15 -> 1.1881694 | L15: ='💰 Precio de Venta'!H16 -> 1.9802823
D16: 10 | E16: Adaptador YYY 67 | F16: Unid. | G16: 2000 | H16: 0.5 | I16: =IF(G16=0,0,G16*H16) -> 1000 | J16: =IF(I16=0,0,I16/$I$507) -> 0.022914085 | K16: ='🧮 Costos x Producto'!K16 -> 2.1217311 | L16: ='💰 Precio de Venta'!H17 -> 3.5362184
D17: 11 | E17: Case Transparente TPU iPhone 15 | F17: Unid. | G17: 480 | H17: 1.21 | I17: =IF(G17=0,0,G17*H17) -> 580.8 | J17: =IF(I17=0,0,I17/$I$507) -> 0.013308501 | K17: ='🧮 Costos x Producto'!K17 -> 5.1345892 | L17: ='💰 Precio de Venta'!H18 -> 8.5576486
D18: 12 | E18: Cable USB-C Trenzado 1m | F18: Unid. | G18: 2880 | H18: 0.68 | I18: =IF(G18=0,0,G18*H18) -> 1958.4 | J18: =IF(I18=0,0,I18/$I$507) -> 0.044874944 | K18: ='🧮 Costos x Producto'!K18 -> 2.8855542 | L18: ='💰 Precio de Venta'!H19 -> 4.8092571
... D34: 28 | E34: Adaptador USB-C a Jack 3.5mm | F34: Unid. | G34: 4800 | H34: 0.28 | I34: =IF(G34=0,0,G34*H34) -> 1344 | J34: =IF(I34=0,0,I34/$I$507) -> 0.03079653 | K34: ='🧮 Costos x Producto'!K34 -> 1.1881694 | L34: ='💰 Precio de Venta'!H35 -> 1.9802823
D35: 29 | F35: Unid. | G35: 0 | H35: 0 | I35: =IF(G35=0,0,G35*H35) -> 0 | J35: =IF(I35=0,0,I35/$I$507) -> 0 | K35: ='🧮 Costos x Producto'!K35 -> 0 | L35: ='💰 Precio de Venta'!H36 -> 0
D36: 30 | F36: Unid. | G36: 0 | H36: 0 | I36: =IF(G36=0,0,G36*H36) -> 0 | J36: =IF(I36=0,0,I36/$I$507) -> 0 | K36: ='🧮 Costos x Producto'!K36 -> 0 | L36: ='💰 Precio de Venta'!H37 -> 0
D37: 31 | F37: Unid. | G37: 0 | H37: 0 | I37: =IF(G37=0,0,G37*H37) -> 0 | J37: =IF(I37=0,0,I37/$I$507) -> 0 | K37: ='🧮 Costos x Producto'!K37 -> 0 | L37: ='💰 Precio de Venta'!H38 -> 0
D38: 32 | F38: Unid. | G38: 0 | H38: 0 | I38: =IF(G38=0,0,G38*H38) -> 0 | J38: =IF(I38=0,0,I38/$I$507) -> 0 | K38: ='🧮 Costos x Producto'!K38 -> 0 | L38: ='💰 Precio de Venta'!H39 -> 0
D39: 33 | F39: Unid. | G39: 0 | H39: 0 | I39: =IF(G39=0,0,G39*H39) -> 0 | J39: =IF(I39=0,0,I39/$I$507) -> 0 | K39: ='🧮 Costos x Producto'!K39 -> 0 | L39: ='💰 Precio de Venta'!H40 -> 0
D40: 34 | F40: Unid. | G40: 0 | H40: 0 | I40: =IF(G40=0,0,G40*H40) -> 0 | J40: =IF(I40=0,0,I40/$I$507) -> 0 | K40: ='🧮 Costos x Producto'!K40 -> 0 | L40: ='💰 Precio de Venta'!H41 -> 0
D41: 35 | F41: Unid. | G41: 0 | H41: 0 | I41: =IF(G41=0,0,G41*H41) -> 0 | J41: =IF(I41=0,0,I41/$I$507) -> 0 | K41: ='🧮 Costos x Producto'!K41 -> 0 | L41: ='💰 Precio de Venta'!H42 -> 0
D42: 36 | F42: Unid. | G42: 0 | H42: 0 | I42: =IF(G42=0,0,G42*H42) -> 0 | J42: =IF(I42=0,0,I42/$I$507) -> 0 | K42: ='🧮 Costos x Producto'!K42 -> 0 | L42: ='💰 Precio de Venta'!H43 -> 0
D43: 37 | F43: Unid. | G43: 0 | H43: 0 | I43: =IF(G43=0,0,G43*H43) -> 0 | J43: =IF(I43=0,0,I43/$I$507) -> 0 | K43: ='🧮 Costos x Producto'!K43 -> 0 | L43: ='💰 Precio de Venta'!H44 -> 0
D44: 38 | F44: Unid. | G44: 0 | H44: 0 | I44: =IF(G44=0,0,G44*H44) -> 0 | J44: =IF(I44=0,0,I44/$I$507) -> 0 | K44: ='🧮 Costos x Producto'!K44 -> 0 | L44: ='💰 Precio de Venta'!H45 -> 0
D45: 39 | F45: Unid. | G45: 0 | H45: 0 | I45: =IF(G45=0,0,G45*H45) -> 0 | J45: =IF(I45=0,0,I45/$I$507) -> 0 | K45: ='🧮 Costos x Producto'!K45 -> 0 | L45: ='💰 Precio de Venta'!H46 -> 0
D46: 40 | F46: Unid. | G46: 0 | H46: 0 | I46: =IF(G46=0,0,G46*H46) -> 0 | J46: =IF(I46=0,0,I46/$I$507) -> 0 | K46: ='🧮 Costos x Producto'!K46 -> 0 | L46: ='💰 Precio de Venta'!H47 -> 0
... D506: 500 | F506: Unid. | G506: 0 | H506: 0 | I506: =IF(G506=0,0,G506*H506) -> 0 | J506: =IF(I506=0,0,I506/$I$507) -> 0 | K506: ='🧮 Costos x Producto'!K506 -> 0 | L506: ='💰 Precio de Venta'!H507 -> 0
D507: TOTAL FOB (USD) | I507: =SUM(I7:I506) -> 43641.28

Sheet 📦 Gastos Importación
D2: 📦 GASTOS DE IMPORTACIÓN (Tercer Elemento)
D3: Ingrese el monto de cada gasto. Los gastos marcados con ⭐ están sujetos a IGV del 18%.
D4: CONCEPTO / GASTO | E4: MONTO (USD) | F4: AFECTO IGV | G4: NOTAS
D5: ⭐ Derecho de Emisión (Seguro) | E5: ='🧾 Tributos Aduana'!F9 -> - | F5: SÍ | G5: Auto-calculado desde Tributos Aduana
D6: ⭐ Handling | E6: 34.03 | F6: SÍ | G6: Manipuleo de la carga
D7: ⭐ Servicio de Descarga | E7: 100.69 | F7: SÍ | G7: Descarga del contenedor
D8: ⭐ Movilización de Carga | E8: 36.46 | F8: SÍ | G8: Traslado interno del terminal
D9: ⭐ Tracción | E9: 48.61 | F9: SÍ | G9: Transporte del contenedor
D10: ⭐ Servicio al Cliente (V°B°) | E10: 12.15 | F10: SÍ | G10: Verificación de pago del flete
D11: ⭐ Gastos Operativos Agente | E11: 70 | F11: SÍ | G11: Gestión del despacho
D12: ⭐ Almacenaje | E12: 121.53 | F12: SÍ | G12: Días de almacén temporal
D13: ⭐ Cargadores / Cuadrilla | E13: 62.5 | F13: SÍ | G13: Personal de carga
D14: ⭐ Serv. Administrativos | E14: 13.89 | F14: SÍ | G14: Documentación
D15: ⭐ Seguro de Contenedor | E15: 41.67 | F15: SÍ | G15: Seguro de la carga en tránsito local
D16: ⭐ Posicionamiento de Carga | E16: 62.5 | F16: SÍ | G16: Reconocimiento físico si aplica
D17: ⭐ Transporte Interno / Última Milla | E17: 104.17 | F17: SÍ | G17: Traslado a almacenes del importador
... D25: Comisiones C/C | E25: 0 | F25: NO | G25: 1.2% CFR si aplica carta de crédito
D26: SUB-TOTAL AFECTOS A IGV (US$) | E26: =E6+E7+E8+E9+E10+E11+E12+E13+E14+E15+E16+E17+E18+E19+E20 -> 997.24 | F26: =SUM(E6:E20)*'📋 Datos Generales'!E28 -> 179.5032
D27: SUB-TOTAL NO AFECTOS A IGV (US$) | E27: =E21+E22+E23+E24+E25 -> 167.5 | F27: No genera IGV
D28: ⭐ TOTAL COSTOS IMPORTACIÓN (US$) | E28: ='🧾 Tributos Aduana'!$F$14+'🧾 Tributos Aduana'!$F$17+E26+E27 -> 49782.29
H30: Tipo | I30: US$
H31: Afectos IGV | I31: =E26 -> 997.24
H32: No Afectos | I32: =E27 -> 167.5

Sheet 🧾 Tributos Aduana
E2: 🧾 TRIBUTOS ADUANEROS — CÁLCULO AUTOMÁTICO
E3: Todos los valores se calculan automáticamente. Solo configure los parámetros en '📋 Datos Generales'.
E5: 🛡️ CÁLCULO DEL SEGURO (Prima Neta → Suma Asegurada)
E6: FOB Total (USD) | F6: ='🧾 Factura Comercial'!I507 -> 43641.28 | G6: Valor FOB total de la factura comercial
E7: Flete Internacional (USD) | F7: 2090 | G7: Monto del flete — copiar del BL/AWB
E8: CFR = FOB + Flete (USD) | F8: =F6+F7 -> 45731.28 | G8: Valor CFR = base para calcular SA
E9: Suma Asegurada (USD) | F9: - | G9: SA = CFR / (1 - deducible%) — Fórmula del libro
E10: Prima Neta (USD) | F10: 134.27 | G10: Prima Neta = SA × 24%
E11: D. Emisión Seguro (USD) | F11: =F10*'📋 Datos Generales'!E25 -> 0 | G11: Derecho de Emisión = 3% × Prima Neta → va a Gastos
E12: IGV Seguro (USD) | F12: =SUM(F10:F11)*'📋 Datos Generales'!E28 -> 24.1686 | G12: IGV sobre Prima Neta → va a Crédito Fiscal
E13: Seguro (Prima Neta) → CIF | F13: =F10 -> 134.27 | G13: Prima Neta forma parte del CIF
E14: CIF = CFR + Prima Neta | F14: =F8+F10 -> 45865.55 | G14: CIF = Valor en Aduanas
E16: ⚖️ DEUDA ADUANERA (ADEUDO) — Pago a SUNAT-ADUANAS
E17: Ad Valorem — ADV (USD) | F17: =ROUND(F14*'📋 Datos Generales'!E20,0) -> 2752 | G17: ADV = CIF × Ad Valorem% — redondeado entero
E18: IPM (USD) | F18: =ROUND((F14+F17)*'📋 Datos Generales'!E22,0) -> 972 | G18: IPM = (CIF + ADV) × 2% — redondeado
E19: IGV (USD) | F19: =ROUND((F14+F17)*'📋 Datos Generales'!E21,0) -> 7779 | G19: IGV = (CIF + ADV) × 16% — redondeado
E20: DEUDA ADUANERA = DA (USD) | F20: =F17+F18+F19 -> 11503 | G20: DA = ADV + IPM + IGV
E22: 💸 PERCEPCIÓN IGV Y DERECHOS (costo real)
E23: Percepción IGV (USD) | F23: =ROUND((F14+F20)*'📋 Datos Generales'!E23,2) -> 2007.9 | G23: Base = CIF + DA — tasa según tipo importador
E24: DERECHOS = ADV (USD) | F24: =F17 -> 2752 | G24: Solo el ADV es costo (IPM e IGV = crédito fiscal)
E25: Comisión Agente (USD) | F25: =MAX(F14*'📋 Datos Generales'!E27,100/'📋 Datos Generales'!E19) -> 458.6555 | G25: Máx entre 1% CIF y mín USD 100
F35: Componente | G35: Monto US$
F36: Ad Valorem | G36: =F17 -> 2752
F37: IPM | G37: =F18 -> 972
F38: IGV Aduanas | G38: =F19 -> 7779
F39: Percepción | G39: =F23 -> 2007.9
F42: Componente | G42: Monto US$
F43: FOB | G43: =F6 -> 43641.28
F44: Flete | G44: =F7 -> 2090
F45: Seguro | G45: =F10 -> 134.27

Sheet 🧮 Costos x Producto
D2: 🧮 COSTO DE IMPORTACIÓN POR PRODUCTO (Factor de Prorrateo)
D3: El Costo Unitario se calcula multiplicando el Factor de Prorrateo × FOB Unitario. Factor = C/M Total / FOB Total
D4: COSTO TOTAL DE IMPORTACIÓN (US$) | G4: ='📦 Gastos Importación'!E28 -> 49782.29 | I4: =G4*'📋 Datos Generales'!E19 -> 185190.12
D5: FACTOR DE PRORRATEO = C/M Total (US$) / FOB Total (US$) | G5: =IF('🧾 Factura Comercial'!I507=0,0,G4/'🧾 Factura Comercial'!I507) -> 1.1407156
D6: # | E6: PRODUCTO | F6: CANTIDAD | G6: FOB UNIT. (USD) | H6: FOB TOTAL (USD) | I6: % PARTICIPACÓN | J6: C/M UNIT. (USD) | K6: C/M UNIT. (PEN)
D7: 1 | E7: ='🧾 Factura Comercial'!E7 -> Case Transparente TPU iPhone 15 | F7: ='🧾 Factura Comercial'!G7 -> 480 | G7: ='🧾 Factura Comercial'!H7 -> 1.21 | H7: ='🧾 Factura Comercial'!I7 -> 580.8 | I7: ='🧾 Factura Comercial'!J7 -> 0.013308501 | J7: =IF($G$5=0,0,$G$5*G7) -> 1.3802659 | K7: =J7*'📋 Datos Generales'!$E$19 -> 5.1345892
D8: 2 | E8: ='🧾 Factura Comercial'!E8 -> Cable USB-C Trenzado 1m | F8: ='🧾 Factura Comercial'!G8 -> 2880 | G8: ='🧾 Factura Comercial'!H8 -> 0.68 | H8: ='🧾 Factura Comercial'!I8 -> 1958.4 | I8: ='🧾 Factura Comercial'!J8 -> 0.044874944 | J8: =IF($G$5=0,0,$G$5*G8) -> 0.77568663 | K8: =J8*'📋 Datos Generales'!$E$19 -> 2.8855542
D9: 3 | E9: ='🧾 Factura Comercial'!E9 -> Protector Pantalla Vidrio Templado | F9: ='🧾 Factura Comercial'!G9 -> 2880 | G9: ='🧾 Factura Comercial'!H9 -> 0.4 | H9: ='🧾 Factura Comercial'!I9 -> 1152 | I9: ='🧾 Factura Comercial'!J9 -> 0.026397026 | J9: =IF($G$5=0,0,$G$5*G9) -> 0.45628625 | K9: =J9*'📋 Datos Generales'!$E$19 -> 1.6973849
D10: 4 | E10: ='🧾 Factura Comercial'!E10 -> Audífonos In-Ear con Micrófono | F10: ='🧾 Factura Comercial'!G10 -> 10224 | G10: ='🧾 Factura Comercial'!H10 -> 0.34 | H10: ='🧾 Factura Comercial'!I10 -> 3476.16 | I10: ='🧾 Factura Comercial'!J10 -> 0.079653026 | J10: =IF($G$5=0,0,$G$5*G10) -> 0.38784331 | K10: =J10*'📋 Datos Generales'!$E$19 -> 1.4427771
D11: 5 | E11: ='🧾 Factura Comercial'!E11 -> Cable Micro USB 2m Nylon | F11: ='🧾 Factura Comercial'!G11 -> 8640 | G11: ='🧾 Factura Comercial'!H11 -> 0.26 | H11: ='🧾 Factura Comercial'!I11 -> 2246.4 | I11: ='🧾 Factura Comercial'!J11 -> 0.051474201 | J11: =IF($G$5=0,0,$G$5*G11) -> 0.29658606 | K11: =J11*'📋 Datos Generales'!$E$19 -> 1.1033002
D12: 6 | E12: ='🧾 Factura Comercial'!E12 -> Soporte Anillo Pop Socket Metálico | F12: ='🧾 Factura Comercial'!G12 -> 2160 | G12: ='🧾 Factura Comercial'!H12 -> 0.29 | H12: ='🧾 Factura Comercial'!I12 -> 626.4 | I12: ='🧾 Factura Comercial'!J12 -> 0.014353383 | J12: =IF($G$5=0,0,$G$5*G12) -> 0.33080753 | K12: =J12*'📋 Datos Generales'!$E$19 -> 1.230604
D13: 7 | E13: ='🧾 Factura Comercial'!E13 -> Cargador Inalámbrico 15W Qi | F13: ='🧾 Factura Comercial'!G13 -> 240 | G13: ='🧾 Factura Comercial'!H13 -> 5.71 | H13: ='🧾 Factura Comercial'!I13 -> 1370.4 | I13: ='🧾 Factura Comercial'!J13 -> 0.031401462 | J13: =IF($G$5=0,0,$G$5*G13) -> 6.5134862 | K13: =J13*'📋 Datos Generales'!$E$19 -> 24.230169
D14: 8 | E14: ='🧾 Factura Comercial'!E14 -> Case Wallet Cuero PU Samsung S24 | F14: ='🧾 Factura Comercial'!G14 -> 1920 | G14: ='🧾 Factura Comercial'!H14 -> 0.76 | H14: ='🧾 Factura Comercial'!I14 -> 1459.2 | I14: ='🧾 Factura Comercial'!J14 -> 0.033436233 | J14: =IF($G$5=0,0,$G$5*G14) -> 0.86694388 | K14: =J14*'📋 Datos Generales'!$E$19 -> 3.2250312
D15: 9 | E15: ='🧾 Factura Comercial'!E15 -> Adaptador USB-C a Jack 3.5mm | F15: ='🧾 Factura Comercial'!G15 -> 4800 | G15: ='🧾 Factura Comercial'!H15 -> 0.28 | H15: ='🧾 Factura Comercial'!I15 -> 1344 | I15: ='🧾 Factura Comercial'!J15 -> 0.03079653 | J15: =IF($G$5=0,0,$G$5*G15) -> 0.31940038 | K15: =J15*'📋 Datos Generales'!$E$19 -> 1.1881694
D16: 10 | E16: ='🧾 Factura Comercial'!E16 -> Adaptador YYY 67 | F16: ='🧾 Factura Comercial'!G16 -> 2000 | G16: ='🧾 Factura Comercial'!H16 -> 0.5 | H16: ='🧾 Factura Comercial'!I16 -> 1000 | I16: ='🧾 Factura Comercial'!J16 -> 0.022914085 | J16: =IF($G$5=0,0,$G$5*G16) -> 0.57035781 | K16: =J16*'📋 Datos Generales'!$E$19 -> 2.1217311
D17: 11 | E17: ='🧾 Factura Comercial'!E17 -> Case Transparente TPU iPhone 15 | F17: ='🧾 Factura Comercial'!G17 -> 480 | G17: ='🧾 Factura Comercial'!H17 -> 1.21 | H17: ='🧾 Factura Comercial'!I17 -> 580.8 | I17: ='🧾 Factura Comercial'!J17 -> 0.013308501 | J17: =IF($G$5=0,0,$G$5*G17) -> 1.3802659 | K17: =J17*'📋 Datos Generales'!$E$19 -> 5.1345892
D18: 12 | E18: ='🧾 Factura Comercial'!E18 -> Cable USB-C Trenzado 1m | F18: ='🧾 Factura Comercial'!G18 -> 2880 | G18: ='🧾 Factura Comercial'!H18 -> 0.68 | H18: ='🧾 Factura Comercial'!I18 -> 1958.4 | I18: ='🧾 Factura Comercial'!J18 -> 0.044874944 | J18: =IF($G$5=0,0,$G$5*G18) -> 0.77568663 | K18: =J18*'📋 Datos Generales'!$E$19 -> 2.8855542
... D505: 499 | E505: ='🧾 Factura Comercial'!E505 -> 0 | F505: ='🧾 Factura Comercial'!G505 -> 0 | G505: ='🧾 Factura Comercial'!H505 -> 0 | H505: ='🧾 Factura Comercial'!I505 -> 0 | I505: ='🧾 Factura Comercial'!J505 -> 0 | J505: =IF($G$5=0,0,$G$5*G505) -> 0 | K505: =J505*'📋 Datos Generales'!$E$19 -> 0

Sheet 💰 Precio de Venta
D2: 💰 PRECIO DE VENTA — POLÍTICA DE UTILIDADES
D3: Ingrese su margen de ganancia deseado. VV = Costo Total / (1 - Margen%) — Precio de Venta incluye IGV (18%).
D4: MARGEN DE UTILIDAD GLOBAL (aplica a todos — puedes personalizar por producto ↓) | H4: 0.4
D5: VALOR DE VENTA TOTAL SIN IGV USD | H5: ='📦 Gastos Importación'!E28*H4 -> 19912.916
D6: FACTOR DE PRORRATEO = PV TOTAL / FOB TOTAL | H6: =('📦 Gastos Importación'!E28+H5)/'🧾 Factura Comercial'!I507 -> 1.5970019
D7: # | E7: PRODUCTO | F7: C/M UNIT. (PEN) | G7: MARGEN % | H7: VALOR VENTA UNIT. (S/.) | I7: PRECIO VENTA UNIT. c/IGV (S/.) | J7: GANANCIA UNIT. (S/.) | K7: PUNTO EQUILIBRIO
D8: 1 | E8: ='🧾 Factura Comercial'!E7 -> Case Transparente TPU iPhone 15 | F8: ='🧮 Costos x Producto'!K7 -> 5.1345892 | G8: =$H$4 -> 0.4 | H8: =IF(F8=0,0,F8/(1-G8)) -> 8.5576486 | I8: =IF(H8=0,0,H8*(1+'📋 Datos Generales'!$E$28)) -> 10.098025 | J8: =IF(H8=0,0,H8-F8) -> 3.4230594 | K8: =IF(OR(I8=0,'🧾 Factura Comercial'!G7=0),0,CEILING('🧮 Costos x Producto'!J7*'🧾 Factura Comercial'!G7/I8,1)) -> 66
D9: 2 | E9: ='🧾 Factura Comercial'!E8 -> Cable USB-C Trenzado 1m | F9: ='🧮 Costos x Producto'!K8 -> 2.8855542 | G9: =$H$4 -> 0.4 | H9: =IF(F9=0,0,F9/(1-G9)) -> 4.8092571 | I9: =IF(H9=0,0,H9*(1+'📋 Datos Generales'!$E$28)) -> 5.6749233 | J9: =IF(H9=0,0,H9-F9) -> 1.9237028 | K9: =IF(OR(I9=0,'🧾 Factura Comercial'!G8=0),0,CEILING('🧮 Costos x Producto'!J8*'🧾 Factura Comercial'!G8/I9,1)) -> 394
D10: 3 | E10: ='🧾 Factura Comercial'!E9 -> Protector Pantalla Vidrio Templado | F10: ='🧮 Costos x Producto'!K9 -> 1.6973849 | G10: 0.4 | H10: =IF(F10=0,0,F10/(1-G10)) -> 2.8289748 | I10: =IF(H10=0,0,H10*(1+'📋 Datos Generales'!$E$28)) -> 3.3381902 | J10: =IF(H10=0,0,H10-F10) -> 1.1315899 | K10: =IF(OR(I10=0,'🧾 Factura Comercial'!G9=0),0,CEILING('🧮 Costos x Producto'!J9*'🧾 Factura Comercial'!G9/I10,1)) -> 394
D11: 4 | E11: ='🧾 Factura Comercial'!E10 -> Audífonos In-Ear con Micrófono | F11: ='🧮 Costos x Producto'!K10 -> 1.4427771 | G11: =$H$4 -> 0.4 | H11: =IF(F11=0,0,F11/(1-G11)) -> 2.4046285 | I11: =IF(H11=0,0,H11*(1+'📋 Datos Generales'!$E$28)) -> 2.8374617 | J11: =IF(H11=0,0,H11-F11) -> 0.96185142 | K11: =IF(OR(I11=0,'🧾 Factura Comercial'!G10=0),0,CEILING('🧮 Costos x Producto'!J10*'🧾 Factura Comercial'!G10/I11,1)) -> 1398
D12: 5 | E12: ='🧾 Factura Comercial'!E11 -> Cable Micro USB 2m Nylon | F12: ='🧮 Costos x Producto'!K11 -> 1.1033002 | G12: =$H$4 -> 0.4 | H12: =IF(F12=0,0,F12/(1-G12)) -> 1.8388336 | I12: =IF(H12=0,0,H12*(1+'📋 Datos Generales'!$E$28)) -> 2.1698236 | J12: =IF(H12=0,0,H12-F12) -> 0.73553344 | K12: =IF(OR(I12=0,'🧾 Factura Comercial'!G11=0),0,CEILING('🧮 Costos x Producto'!J11*'🧾 Factura Comercial'!G11/I12,1)) -> 1181
D13: 6 | E13: ='🧾 Factura Comercial'!E12 -> Soporte Anillo Pop Socket Metálico | F13: ='🧮 Costos x Producto'!K12 -> 1.230604 | G13: =$H$4 -> 0.4 | H13: =IF(F13=0,0,F13/(1-G13)) -> 2.0510067 | I13: =IF(H13=0,0,H13*(1+'📋 Datos Generales'!$E$28)) -> 2.4201879 | J13: =IF(H13=0,0,H13-F13) -> 0.82040268 | K13: =IF(OR(I13=0,'🧾 Factura Comercial'!G12=0),0,CEILING('🧮 Costos x Producto'!J12*'🧾 Factura Comercial'!G12/I13,1)) -> 296
D14: 7 | E14: ='🧾 Factura Comercial'!E13 -> Cargador Inalámbrico 15W Qi | F14: ='🧮 Costos x Producto'!K13 -> 24.230169 | G14: =$H$4 -> 0.4 | H14: =IF(F14=0,0,F14/(1-G14)) -> 40.383615 | I14: =IF(H14=0,0,H14*(1+'📋 Datos Generales'!$E$28)) -> 47.652665 | J14: =IF(H14=0,0,H14-F14) -> 16.153446 | K14: =IF(OR(I14=0,'🧾 Factura Comercial'!G13=0),0,CEILING('🧮 Costos x Producto'!J13*'🧾 Factura Comercial'!G13/I14,1)) -> 33
D15: 8 | E15: ='🧾 Factura Comercial'!E14 -> Case Wallet Cuero PU Samsung S24 | F15: ='🧮 Costos x Producto'!K14 -> 3.2250312 | G15: =$H$4 -> 0.4 | H15: =IF(F15=0,0,F15/(1-G15)) -> 5.375052 | I15: =IF(H15=0,0,H15*(1+'📋 Datos Generales'!$E$28)) -> 6.3425614 | J15: =IF(H15=0,0,H15-F15) -> 2.1500208 | K15: =IF(OR(I15=0,'🧾 Factura Comercial'!G14=0),0,CEILING('🧮 Costos x Producto'!J14*'🧾 Factura Comercial'!G14/I15,1)) -> 263
D16: 9 | E16: ='🧾 Factura Comercial'!E15 -> Adaptador USB-C a Jack 3.5mm | F16: ='🧮 Costos x Producto'!K15 -> 1.1881694 | G16: =$H$4 -> 0.4 | H16: =IF(F16=0,0,F16/(1-G16)) -> 1.9802823 | I16: =IF(H16=0,0,H16*(1+'📋 Datos Generales'!$E$28)) -> 2.3367331 | J16: =IF(H16=0,0,H16-F16) -> 0.79211293 | K16: =IF(OR(I16=0,'🧾 Factura Comercial'!G15=0),0,CEILING('🧮 Costos x Producto'!J15*'🧾 Factura Comercial'!G15/I16,1)) -> 657
D17: 10 | E17: ='🧾 Factura Comercial'!E16 -> Adaptador YYY 67 | F17: ='🧮 Costos x Producto'!K16 -> 2.1217311 | G17: =$H$4 -> 0.4 | H17: =IF(F17=0,0,F17/(1-G17)) -> 3.5362184 | I17: =IF(H17=0,0,H17*(1+'📋 Datos Generales'!$E$28)) -> 4.1727378 | J17: =IF(H17=0,0,H17-F17) -> 1.4144874 | K17: =IF(OR(I17=0,'🧾 Factura Comercial'!G16=0),0,CEILING('🧮 Costos x Producto'!J16*'🧾 Factura Comercial'!G16/I17,1)) -> 274
D18: 11 | E18: ='🧾 Factura Comercial'!E17 -> Case Transparente TPU iPhone 15 | F18: ='🧮 Costos x Producto'!K17 -> 5.1345892 | G18: =$H$4 -> 0.4 | H18: =IF(F18=0,0,F18/(1-G18)) -> 8.5576486 | I18: =IF(H18=0,0,H18*(1+'📋 Datos Generales'!$E$28)) -> 10.098025 | J18: =IF(H18=0,0,H18-F18) -> 3.4230594 | K18: =IF(OR(I18=0,'🧾 Factura Comercial'!G17=0),0,CEILING('🧮 Costos x Producto'!J17*'🧾 Factura Comercial'!G17/I18,1)) -> 66
D19: 12 | E19: ='🧾 Factura Comercial'!E18 -> Cable USB-C Trenzado 1m | F19: ='🧮 Costos x Producto'!K18 -> 2.8855542 | G19: =$H$4 -> 0.4 | H19: =IF(F19=0,0,F19/(1-G19)) -> 4.8092571 | I19: =IF(H19=0,0,H19*(1+'📋 Datos Generales'!$E$28)) -> 5.6749233 | J19: =IF(H19=0,0,H19-F19) -> 1.9237028 | K19: =IF(OR(I19=0,'🧾 Factura Comercial'!G18=0),0,CEILING('🧮 Costos x Producto'!J18*'🧾 Factura Comercial'!G18/I19,1)) -> 394
D20: 13 | E20: ='🧾 Factura Comercial'!E19 -> Protector Pantalla Vidrio Templado | F20: ='🧮 Costos x Producto'!K19 -> 1.6973849 | G20: =$H$4 -> 0.4 | H20: =IF(F20=0,0,F20/(1-G20)) -> 2.8289748 | I20: =IF(H20=0,0,H20*(1+'📋 Datos Generales'!$E$28)) -> 3.3381902 | J20: =IF(H20=0,0,H20-F20) -> 1.1315899 | K20: =IF(OR(I20=0,'🧾 Factura Comercial'!G19=0),0,CEILING('🧮 Costos x Producto'!J19*'🧾 Factura Comercial'!G19/I20,1)) -> 394
D21: 14 | E21: ='🧾 Factura Comercial'!E20 -> Audífonos In-Ear con Micrófono | F21: ='🧮 Costos x Producto'!K20 -> 1.4427771 | G21: =$H$4 -> 0.4 | H21: =IF(F21=0,0,F21/(1-G21)) -> 2.4046285 | I21: =IF(H21=0,0,H21*(1+'📋 Datos Generales'!$E$28)) -> 2.8374617 | J21: =IF(H21=0,0,H21-F21) -> 0.96185142 | K21: =IF(OR(I21=0,'🧾 Factura Comercial'!G20=0),0,CEILING('🧮 Costos x Producto'!J20*'🧾 Factura Comercial'!G20/I21,1)) -> 1398
D22: 15 | E22: ='🧾 Factura Comercial'!E21 -> Cable Micro USB 2m Nylon | F22: ='🧮 Costos x Producto'!K21 -> 1.1033002 | G22: =$H$4 -> 0.4 | H22: =IF(F22=0,0,F22/(1-G22)) -> 1.8388336 | I22: =IF(H22=0,0,H22*(1+'📋 Datos Generales'!$E$28)) -> 2.1698236 | J22: =IF(H22=0,0,H22-F22) -> 0.73553344 | K22: =IF(OR(I22=0,'🧾 Factura Comercial'!G21=0),0,CEILING('🧮 Costos x Producto'!J21*'🧾 Factura Comercial'!G21/I22,1)) -> 1181
... D520: 513 | E520: ='🧾 Factura Comercial'!E519 -> 0 | F520: ='🧮 Costos x Producto'!K519 -> 0 | G520: =$H$4 -> 0.4 | H520: =IF(F520=0,0,F520/(1-G520)) -> 0 | I520: =IF(H520=0,0,H520*(1+'📋 Datos Generales'!$E$28)) -> 0 | J520: =IF(H520=0,0,H520-F520) -> 0 | K520: =IF(OR(I520=0,'🧾 Factura Comercial'!G519=0),0,CEILING('🧮 Costos x Producto'!J519*'🧾 Factura Comercial'!G519/I520,1)) -> 0

Sheet 🏦 Crédito Fiscal
B7: 🏦 CRÉDITO FISCAL DEL IMPORTADOR
B8: El Crédito Fiscal se recupera al vender los productos. IPM, IGV y Percepción NO son costo — se recuperan.
B10: 🏦 DETALLE DEL CRÉDITO FISCAL (en US$ — convertir a S/. con TC)
B11: IGV del Seguro (Crédito Fiscal) | C11: ='🧾 Tributos Aduana'!F12 -> 24.1686 | D11: IGV pagado a Cía. de Seguros
B12: IPM — Derechos (Crédito Fiscal) | C12: ='🧾 Tributos Aduana'!F18 -> 972 | D12: IPM pagado a SUNAT-Aduanas
B13: IGV — Derechos (Crédito Fiscal) | C13: ='🧾 Tributos Aduana'!F19 -> 7779 | D13: IGV pagado a SUNAT-Aduanas
B14: Percepción IGV (Crédito Fiscal) | C14: ='🧾 Tributos Aduana'!F23 -> 2007.9 | D14: Percepción pagada — se recupera
B15: IGV Gastos Afectos (Crédito Fiscal) | C15: ='📦 Gastos Importación'!F26 -> 179.5032 | D15: 18% de gastos afectos
B16: ✅ TOTAL CRÉDITO FISCAL (US$) | C16: =C11+C12+C13+C14+C15 -> 10962.572
B17: ✅ TOTAL CRÉDITO FISCAL (S/. PEN) | C17: =C16*'📋 Datos Generales'!E19 -> 40780.767
B19: 📌 ¿QUÉ ES EL CRÉDITO FISCAL? El IGV, IPM y la Percepción que pagas al importar NO son un costo definitivo. Los recuperas cuando vendes tus productos y cobras IGV a tus clientes. El importador declara ante SUNAT: IGV cobrado en ventas - Crédito Fiscal = IGV a pagar. ⚠️ SOLO el Ad Valorem (ADV) es un costo real de importación.

Sheet Detallado por producto
B1: 📦 SECCIÓN 1: IDENTIFICACIÓN DEL PRODUCTO Y VALOR FOB | AG1: 🧮 SECCIÓN 3: COSTO DE IMPORTACIÓN · CRÉDITO FISCAL · PRECIO DE VENTA · MARGENARGEN
A2: DESCRIPCIÓN DEL PRODUCTO | B2: UNIDAD | C2: CANTIDAD (unid.) | D2: FOB UNIT. (US$) | E2: FOB TOTAL (US$) | F2: % PART. FOB | G2: FOB UNIT. (S/.) | H2: FOB TOTAL (S/.) | I2: ADV UNIT. (US$) ⚠️COSTO | J2: ADV TOTAL (US$) ⚠️COSTO | K2: IPM UNIT. (US$) ✅CF | L2: IPM TOTAL (US$) ✅CF | M2: IGV UNIT. (US$) ✅CF | N2: IGV TOTAL (US$) ✅CF | O2: PERCEP. UNIT.(US$) ✅CF | P2: PERCEP. TOTAL.(US$) ✅CF | Q2: DEUDA ADUANERA UNIT. | R2: DEUDA ADUANERA TOTAL | S2: DEUDA ADUANERA UNIT. /S/.) | T2: DEUDA ADUANERA TOTAL (s/.)2 | U2: ADV UNIT. (S/.) | V2: ADV TOTAL. (S/.) | W2: IPM UNIT. (S/.) | X2: IPM TOTAL (S/.)2 | Y2: IGV UNIT. (S/.) | Z2: IGV TOTAL (S/.)2 | AA2: PERCEP. UNIT.(S/.) | AB2: PERCEP. TOTAL.(S/.)2 | AC2: TOTAL PAGO SUNAT UNIT.(US$) | AD2: TOTAL PAGO SUNAT TOTAL(US$) | AE2: TOTAL TRIB. UNIT.(S/.) | AF2: TOTAL TRIB. TOTAL .(S/.) | AG2: GASTOS IMP. UNIT.(US$) | AH2: GASTOS IMP. TOTAL.(US$)2 | AI2: GASTOS IMP. UNIT.(S/.) | AJ2: GASTOS IMP. TOTAL.(S/.)2 | AK2: C/M UNIT. (US$) | AL2: C/M UNIT. (S/.) | AM2: C/M TOTAL (S/.)2 | AN2: ADV UNIT. ⚠️COSTO (US$) | AO2: CF UNIT. ✅RECUP. (US$) | AP2: CF UNIT. ✅RECUP.(S/.) | AQ2: TOTAL CREDITO FISCAL POR PRODUCTO | AR2: MARGEN % | AS2: VALOR VTA. UNIT.(S/.) | AT2: VALOR VTA. TOTAL (S/.) | AU2: PRECIO VTA. c/IGV(S/.) | AV2: GANANCIA UNIT.(S/.) | AW2: GANANCIA TOTAL.(S/.) | AX2: PUNTO EQUILIBRIO | AY2: GANANCIA TOTAL(S/.) | AZ2: % UTILIDAD S/PRECIO | BA2: ROI UNIT. | BB2: CLASIF. MARGEN
A3: ='🧾 Factura Comercial'!E7 -> Case Transparente TPU iPhone 15 | B3: ='🧾 Factura Comercial'!F7 -> Unid. | C3: ='🧾 Factura Comercial'!G7 -> 480 | D3: ='🧾 Factura Comercial'!H7 -> 1.21 | E3: ='🧾 Factura Comercial'!I7 -> 580.8 | F3: =IF('🧾 Tributos Aduana'!$F$6=0,0,'🧾 Factura Comercial'!I7/'🧾 Tributos Aduana'!$F$6) -> 0.013308501 | G3: ='🧾 Factura Comercial'!H7*'📋 Datos Generales'!$E$19 -> 4.5012 | H3: =TABLA_BASE[[#This Row],[FOB UNIT. (S/.)]]*TABLA_BASE[[#This Row],[CANTIDAD (unid.)]] -> 2160.576 | I3: =IF('🧾 Tributos Aduana'!$F$6=0,0,'🧾 Tributos Aduana'!$F$17*('🧾 Factura Comercial'!H7/'🧾 Tributos Aduana'!$F$6)) -> 0.07630207 | J3: =TABLA_BASE[[#This Row],[ADV UNIT. (US$) ⚠️COSTO]]*TABLA_BASE[[#This Row],[CANTIDAD (unid.)]] -> 36.624994 | K3: =IF('🧾 Tributos Aduana'!$F$6=0,0,'🧾 Tributos Aduana'!$F$18*('🧾 Factura Comercial'!H7/'🧾 Tributos Aduana'!$F$6)) -> 0.026949714 | L3: =TABLA_BASE[[#This Row],[IPM UNIT. (US$) ✅CF]]*TABLA_BASE[[#This Row],[CANTIDAD (unid.)]] -> 12.935863 | M3: =IF('🧾 Tributos Aduana'!$F$6=0,0,'🧾 Tributos Aduana'!$F$19*('🧾 Factura Comercial'!H7/'🧾 Tributos Aduana'!$F$6)) -> 0.21568089 | N3: =TABLA_BASE[[#This Row],[IGV UNIT. (US$) ✅CF]]*TABLA_BASE[[#This Row],[CANTIDAD (unid.)]] -> 103.52683 | O3: =IF('🧾 Tributos Aduana'!$F$6=0,0,'🧾 Tributos Aduana'!$F$23*('🧾 Factura Comercial'!H7/'🧾 Tributos Aduana'!$F$6)) -> 0.055671121 | P3: =TABLA_BASE[[#This Row],[PERCEP. UNIT.(US$) ✅CF]]*TABLA_BASE[[#This Row],[CANTIDAD (unid.)]] -> 26.722138 | Q3: =TABLA_BASE[[#This Row],[ADV UNIT. (US$) ⚠️COSTO]]+TABLA_BASE[[#This Row],[IPM UNIT. (US$) ✅CF]]+TABLA_BASE[[#This Row],[IGV UNIT. (US$) ✅CF]] -> 0.31893267 | R3: =TABLA_BASE[[#This Row],[DEUDA ADUANERA UNIT.]]*TABLA_BASE[[#This Row],[CANTIDAD (unid.)]] -> 153.08768 | S3: =TABLA_BASE[[#This Row],[DEUDA ADUANERA UNIT.]]*'📋 Datos Generales'!$E$19 -> 1.1864295 | T3: =TABLA_BASE[[#This Row],[DEUDA ADUANERA TOTAL]]*'📋 Datos Generales'!$E$19 -> 569.48618 | U3: =TABLA_BASE[[#This Row],[ADV UNIT. (US$) ⚠️COSTO]]*'📋 Datos Generales'!$E$19 -> 0.2838437 | V3: =TABLA_BASE[[#This Row],[ADV UNIT. (S/.)]]*TABLA_BASE[[#This Row],[CANTIDAD (unid.)]] -> 136.24498 | W3: =TABLA_BASE[[#This Row],[IPM UNIT. (US$) ✅CF]]*'📋 Datos Generales'!$E$19 -> 0.10025293 | X3: =TABLA_BASE[[#This Row],[IPM UNIT. (S/.)]]*TABLA_BASE[[#This Row],[CANTIDAD (unid.)]] -> 48.121409 | Y3: =TABLA_BASE[[#This Row],[IGV UNIT. (US$) ✅CF]]*'📋 Datos Generales'!$E$19 -> 0.8023329 | Z3: =TABLA_BASE[[#This Row],[IGV UNIT. (S/.)]]*TABLA_BASE[[#This Row],[CANTIDAD (unid.)]] -> 385.11979 | AA3: =TABLA_BASE[[#This Row],[PERCEP. UNIT.(US$) ✅CF]]*'📋 Datos Generales'!$E$19 -> 0.20709657 | AB3: =TABLA_BASE[[#This Row],[PERCEP. UNIT.(S/.)]]*TABLA_BASE[[#This Row],[CANTIDAD (unid.)]] -> 99.406354 | AC3: =TABLA_BASE[[#This Row],[ADV UNIT. (US$) ⚠️COSTO]]+TABLA_BASE[[#This Row],[IPM UNIT. (US$) ✅CF]]+TABLA_BASE[[#This Row],[IGV UNIT. (US$) ✅CF]]+TABLA_BASE[[#This Row],[PERCEP. UNIT.(US$) ✅CF]] -> 0.37460379 | AD3: =TABLA_BASE[[#This Row],[TOTAL PAGO SUNAT UNIT.(US$)]]*TABLA_BASE[[#This Row],[CANTIDAD (unid.)]] -> 179.80982 | AE3: =TABLA_BASE[[#This Row],[TOTAL PAGO SUNAT UNIT.(US$)]]*'📋 Datos Generales'!$E$19 -> 1.3935261 | AF3: =TABLA_BASE[[#This Row],[TOTAL TRIB. UNIT.(S/.)]]*TABLA_BASE[[#This Row],[CANTIDAD (unid.)]] -> 668.89253 | AG3: =IF('🧾 Factura Comercial'!G7=0,0,'📦 Gastos Importación'!$E$28*(IF('🧾 Tributos Aduana'!$F$6=0,0,'🧾 Factura Comercial'!I7/'🧾 Tributos Aduana'!$F$6))/'🧾 Factura Comercial'!G7) -> 1.3802659 | AH3: =TABLA_BASE[[#This Row],[GASTOS IMP. UNIT.(US$)]]*TABLA_BASE[[#This Row],[CANTIDAD (unid.)]] -> 662.52764 | AI3: =TABLA_BASE[[#This Row],[GASTOS IMP. UNIT.(US$)]]*'📋 Datos Generales'!$E$19 -> 5.1345892 | AJ3: =TABLA_BASE[[#This Row],[GASTOS IMP. UNIT.(S/.)]]*TABLA_BASE[[#This Row],[CANTIDAD (unid.)]] -> 2464.6028 | AK3: ='🧮 Costos x Producto'!J7 -> 1.3802659 | AL3: ='🧮 Costos x Producto'!K7 -> 5.1345892 | AM3: =TABLA_BASE[[#This Row],[C/M UNIT. (S/.)]]*TABLA_BASE[[#This Row],[CANTIDAD (unid.)]] -> 2464.6028 | AN3: =IF('🧾 Factura Comercial'!G7=0,0,'🧾 Tributos Aduana'!$F$17*(IF('🧾 Tributos Aduana'!$F$6=0,0,'🧾 Factura Comercial'!I7/'🧾 Tributos Aduana'!$F$6))/'🧾 Factura Comercial'!G7) -> 0.07630207 | AO3: =IF('🧾 Factura Comercial'!G7=0,0,'🏦 Crédito Fiscal'!$C$16*(IF('🧾 Tributos Aduana'!$F$6=0,0,'🧾 Factura Comercial'!I7/'🧾 Tributos Aduana'!$F$6))/'🧾 Factura Comercial'!G7) -> 0.30394874 | AP3: =TABLA_BASE[[#This Row],[CF UNIT. ✅RECUP. (US$)]]*'📋 Datos Generales'!$E$19 -> 1.1306893 | AQ3: =TABLA_BASE[[#This Row],[CF UNIT. ✅RECUP.(S/.)]]*TABLA_BASE[[#This Row],[CANTIDAD (unid.)]] -> 542.73086 | AR3: ='💰 Precio de Venta'!G8 -> 0.4 | AS3: ='💰 Precio de Venta'!H8 -> 8.5576486 | AT3: =TABLA_BASE[[#This Row],[VALOR VTA. UNIT.(S/.)]]*TABLA_BASE[[#This Row],[CANTIDAD (unid.)]] -> 4107.6713 | AU3: ='💰 Precio de Venta'!I8 -> 10.098025 | AV3: ='💰 Precio de Venta'!J8 -> 3.4230594 | AW3: =TABLA_BASE[[#This Row],[GANANCIA UNIT.(S/.)]]*TABLA_BASE[[#This Row],[CANTIDAD (unid.)]] -> 1643.0685 | AX3: ='💰 Precio de Venta'!K8 -> 66 | AY3: =TABLA_BASE[[#This Row],[GANANCIA UNIT.(S/.)]]*'🧾 Factura Comercial'!G7 -> 1643.0685 | AZ3: =IF(TABLA_BASE[[#This Row],[PRECIO VTA. c/IGV(S/.)]]=0,0,TABLA_BASE[[#This Row],[GANANCIA UNIT.(S/.)]]/TABLA_BASE[[#This Row],[PRECIO VTA. c/IGV(S/.)]]) -> 0.33898305 | BA3: =IF(TABLA_BASE[[#This Row],[C/M UNIT. (S/.)]]=0,0,TABLA_BASE[[#This Row],[GANANCIA UNIT.(S/.)]]/TABLA_BASE[[#This Row],[C/M UNIT. (S/.)]]) -> 0.66666667 | BB3: =IF(TABLA_BASE[[#This Row],[MARGEN %]]>=0.5,"🟢 ALTO",IF(TABLA_BASE[[#This Row],[MARGEN %]]>=0.3,"🟡 MEDIO","🔴 BAJO")) -> 🟡 MEDIO
A4: ='🧾 Factura Comercial'!E8 -> Cable USB-C Trenzado 1m | B4: ='🧾 Factura Comercial'!F8 -> Unid. | C4: ='🧾 Factura Comercial'!G8 -> 2880 | D4: ='🧾 Factura Comercial'!H8 -> 0.68 | E4: ='🧾 Factura Comercial'!I8 -> 1958.4 | F4: =IF('🧾 Tributos Aduana'!$F$6=0,0,'🧾 Factura Comercial'!I8/'🧾 Tributos Aduana'!$F$6) -> 0.044874944 | G4: ='🧾 Factura Comercial'!H8*'📋 Datos Generales'!$E$19 -> 2.5296 | H4: =TABLA_BASE[[#This Row],[FOB UNIT. (S/.)]]*TABLA_BASE[[#This Row],[CANTIDAD (unid.)]] -> 7285.248 | I4: =IF('🧾 Tributos Aduana'!$F$6=0,0,'🧾 Tributos Aduana'!$F$17*('🧾 Factura Comercial'!H8/'🧾 Tributos Aduana'!$F$6)) -> 0.042880502 | J4: =TABLA_BASE[[#This Row],[ADV UNIT. (US$) ⚠️COSTO]]*TABLA_BASE[[#This Row],[CANTIDAD (unid.)]] -> 123.49585 | K4: =IF('🧾 Tributos Aduana'!$F$6=0,0,'🧾 Tributos Aduana'!$F$18*('🧾 Factura Comercial'!H8/'🧾 Tributos Aduana'!$F$6)) -> 0.015145294 | L4: =TABLA_BASE[[#This Row],[IPM UNIT. (US$) ✅CF]]*TABLA_BASE[[#This Row],[CANTIDAD (unid.)]] -> 43.618446 | M4: =IF('🧾 Tributos Aduana'!$F$6=0,0,'🧾 Tributos Aduana'!$F$19*('🧾 Factura Comercial'!H8/'🧾 Tributos Aduana'!$F$6)) -> 0.12120909 | N4: =TABLA_BASE[[#This Row],[IGV UNIT. (US$) ✅CF]]*TABLA_BASE[[#This Row],[CANTIDAD (unid.)]] -> 349.08219 | O4: =IF('🧾 Tributos Aduana'!$F$6=0,0,'🧾 Tributos Aduana'!$F$23*('🧾 Factura Comercial'!H8/'🧾 Tributos Aduana'!$F$6)) -> 0.03128625 | P4: =TABLA_BASE[[#This Row],[PERCEP. UNIT.(US$) ✅CF]]*TABLA_BASE[[#This Row],[CANTIDAD (unid.)]] -> 90.1044 | Q4: =TABLA_BASE[[#This Row],[ADV UNIT. (US$) ⚠️COSTO]]+TABLA_BASE[[#This Row],[IPM UNIT. (US$) ✅CF]]+TABLA_BASE[[#This Row],[IGV UNIT. (US$) ✅CF]] -> 0.17923489 | R4: =TABLA_BASE[[#This Row],[DEUDA ADUANERA UNIT.]]*TABLA_BASE[[#This Row],[CANTIDAD (unid.)]] -> 516.19648 | S4: =TABLA_BASE[[#This Row],[DEUDA ADUANERA UNIT.]]*'📋 Datos Generales'!$E$19 -> 0.66675379 | T4: =TABLA_BASE[[#This Row],[DEUDA ADUANERA TOTAL]]*'📋 Datos Generales'!$E$19 -> 1920.2509 | U4: =TABLA_BASE[[#This Row],[ADV UNIT. (US$) ⚠️COSTO]]*'📋 Datos Generales'!$E$19 -> 0.15951547 | V4: =TABLA_BASE[[#This Row],[ADV UNIT. (S/.)]]*TABLA_BASE[[#This Row],[CANTIDAD (unid.)]] -> 459.40455 | W4: =TABLA_BASE[[#This Row],[IPM UNIT. (US$) ✅CF]]*'📋 Datos Generales'!$E$19 -> 0.056340492 | X4: =TABLA_BASE[[#This Row],[IPM UNIT. (S/.)]]*TABLA_BASE[[#This Row],[CANTIDAD (unid.)]] -> 162.26062 | Y4: =TABLA_BASE[[#This Row],[IGV UNIT. (US$) ✅CF]]*'📋 Datos Generales'!$E$19 -> 0.45089783 | Z4: =TABLA_BASE[[#This Row],[IGV UNIT. (S/.)]]*TABLA_BASE[[#This Row],[CANTIDAD (unid.)]] -> 1298.5857 | AA4: =TABLA_BASE[[#This Row],[PERCEP. UNIT.(US$) ✅CF]]*'📋 Datos Generales'!$E$19 -> 0.11638485 | AB4: =TABLA_BASE[[#This Row],[PERCEP. UNIT.(S/.)]]*TABLA_BASE[[#This Row],[CANTIDAD (unid.)]] -> 335.18837 | AC4: =TABLA_BASE[[#This Row],[ADV UNIT. (US$) ⚠️COSTO]]+TABLA_BASE[[#This Row],[IPM UNIT. (US$) ✅CF]]+TABLA_BASE[[#This Row],[IGV UNIT. (US$) ✅CF]]+TABLA_BASE[[#This Row],[PERCEP. UNIT.(US$) ✅CF]] -> 0.21052114 | AD4: =TABLA_BASE[[#This Row],[TOTAL PAGO SUNAT UNIT.(US$)]]*TABLA_BASE[[#This Row],[CANTIDAD (unid.)]] -> 606.30088 | AE4: =TABLA_BASE[[#This Row],[TOTAL PAGO SUNAT UNIT.(US$)]]*'📋 Datos Generales'!$E$19 -> 0.78313864 | AF4: =TABLA_BASE[[#This Row],[TOTAL TRIB. UNIT.(S/.)]]*TABLA_BASE[[#This Row],[CANTIDAD (unid.)]] -> 2255.4393 | AG4: =IF('🧾 Factura Comercial'!G8=0,0,'📦 Gastos Importación'!$E$28*(IF('🧾 Tributos Aduana'!$F$6=0,0,'🧾 Factura Comercial'!I8/'🧾 Tributos Aduana'!$F$6))/'🧾 Factura Comercial'!G8) -> 0.77568663 | AH4: =TABLA_BASE[[#This Row],[GASTOS IMP. UNIT.(US$)]]*TABLA_BASE[[#This Row],[CANTIDAD (unid.)]] -> 2233.9775 | AI4: =TABLA_BASE[[#This Row],[GASTOS IMP. UNIT.(US$)]]*'📋 Datos Generales'!$E$19 -> 2.8855542 | AJ4: =TABLA_BASE[[#This Row],[GASTOS IMP. UNIT.(S/.)]]*TABLA_BASE[[#This Row],[CANTIDAD (unid.)]] -> 8310.3962 | AK4: ='🧮 Costos x Producto'!J8 -> 0.77568663 | AL4: ='🧮 Costos x Producto'!K8 -> 2.8855542 | AM4: =TABLA_BASE[[#This Row],[C/M UNIT. (S/.)]]*TABLA_BASE[[#This Row],[CANTIDAD (unid.)]] -> 8310.3962 | AN4: =IF('🧾 Factura Comercial'!G8=0,0,'🧾 Tributos Aduana'!$F$17*(IF('🧾 Tributos Aduana'!$F$6=0,0,'🧾 Factura Comercial'!I8/'🧾 Tributos Aduana'!$F$6))/'🧾 Factura Comercial'!G8) -> 0.042880502 | AO4: =IF('🧾 Factura Comercial'!G8=0,0,'🏦 Crédito Fiscal'!$C$16*(IF('🧾 Tributos Aduana'!$F$6=0,0,'🧾 Factura Comercial'!I8/'🧾 Tributos Aduana'!$F$6))/'🧾 Factura Comercial'!G8) -> 0.17081417 | AP4: =TABLA_BASE[[#This Row],[CF UNIT. ✅RECUP. (US$)]]*'📋 Datos Generales'!$E$19 -> 0.6354287 | AQ4: =TABLA_BASE[[#This Row],[CF UNIT. ✅RECUP.(S/.)]]*TABLA_BASE[[#This Row],[CANTIDAD (unid.)]] -> 1830.0346 | AR4: ='💰 Precio de Venta'!G9 -> 0.4 | AS4: ='💰 Precio de Venta'!H9 -> 4.8092571 | AT4: =TABLA_BASE[[#This Row],[VALOR VTA. UNIT.(S/.)]]*TABLA_BASE[[#This Row],[CANTIDAD (unid.)]] -> 13850.66 | AU4: ='💰 Precio de Venta'!I9 -> 5.6749233 | AV4: ='💰 Precio de Venta'!J9 -> 1.9237028 | AW4: =TABLA_BASE[[#This Row],[GANANCIA UNIT.(S/.)]]*TABLA_BASE[[#This Row],[CANTIDAD (unid.)]] -> 5540.2642 | AX4: ='💰 Precio de Venta'!K9 -> 394 | AY4: =TABLA_BASE[[#This Row],[GANANCIA UNIT.(S/.)]]*'🧾 Factura Comercial'!G8 -> 5540.2642 | AZ4: =IF(TABLA_BASE[[#This Row],[PRECIO VTA. c/IGV(S/.)]]=0,0,TABLA_BASE[[#This Row],[GANANCIA UNIT.(S/.)]]/TABLA_BASE[[#This Row],[PRECIO VTA. c/IGV(S/.)]]) -> 0.33898305 | BA4: =IF(TABLA_BASE[[#This Row],[C/M UNIT. (S/.)]]=0,0,TABLA_BASE[[#This Row],[GANANCIA UNIT.(S/.)]]/TABLA_BASE[[#This Row],[C/M UNIT. (S/.)]]) -> 0.66666667 | BB4: =IF(TABLA_BASE[[#This Row],[MARGEN %]]>=0.5,"🟢 ALTO",IF(TABLA_BASE[[#This Row],[MARGEN %]]>=0.3,"🟡 MEDIO","🔴 BAJO")) -> 🟡 MEDIO
A5: ='🧾 Factura Comercial'!E9 -> Protector Pantalla Vidrio Templado | B5: ='🧾 Factura Comercial'!F9 -> Unid. | C5: ='🧾 Factura Comercial'!G9 -> 2880 | D5: ='🧾 Factura Comercial'!H9 -> 0.4 | E5: ='🧾 Factura Comercial'!I9 -> 1152 | F5: =IF('🧾 Tributos Aduana'!$F$6=0,0,'🧾 Factura Comercial'!I9/'🧾 Tributos Aduana'!$F$6) -> 0.026397026 | G5: ='🧾 Factura Comercial'!H9*'📋 Datos Generales'!$E$19 -> 1.488 | H5: =TABLA_BASE[[#This Row],[FOB UNIT. (S/.)]]*TABLA_BASE[[#This Row],[CANTIDAD (unid.)]] -> 4285.44 | I5: =IF('🧾 Tributos Aduana'!$F$6=0,0,'🧾 Tributos Aduana'!$F$17*('🧾 Factura Comercial'!H9/'🧾 Tributos Aduana'!$F$6)) -> 0.025223825 | J5: =TABLA_BASE[[#This Row],[ADV UNIT. (US$) ⚠️COSTO]]*TABLA_BASE[[#This Row],[CANTIDAD (unid.)]] -> 72.644615 | K5: =IF('🧾 Tributos Aduana'!$F$6=0,0,'🧾 Tributos Aduana'!$F$18*('🧾 Factura Comercial'!H9/'🧾 Tributos Aduana'!$F$6)) -> 0.0089089963 | L5: =TABLA_BASE[[#This Row],[IPM UNIT. (US$) ✅CF]]*TABLA_BASE[[#This Row],[CANTIDAD (unid.)]] -> 25.657909 | M5: =IF('🧾 Tributos Aduana'!$F$6=0,0,'🧾 Tributos Aduana'!$F$19*('🧾 Factura Comercial'!H9/'🧾 Tributos Aduana'!$F$6)) -> 0.071299467 | N5: =TABLA_BASE[[#This Row],[IGV UNIT. (US$) ✅CF]]*TABLA_BASE[[#This Row],[CANTIDAD (unid.)]] -> 205.34246 | O5: =IF('🧾 Tributos Aduana'!$F$6=0,0,'🧾 Tributos Aduana'!$F$23*('🧾 Factura Comercial'!H9/'🧾 Tributos Aduana'!$F$6)) -> 0.018403677 | P5: =TABLA_BASE[[#This Row],[PERCEP. UNIT.(US$) ✅CF]]*TABLA_BASE[[#This Row],[CANTIDAD (unid.)]] -> 53.002588 | Q5: =TABLA_BASE[[#This Row],[ADV UNIT. (US$) ⚠️COSTO]]+TABLA_BASE[[#This Row],[IPM UNIT. (US$) ✅CF]]+TABLA_BASE[[#This Row],[IGV UNIT. (US$) ✅CF]] -> 0.10543229 | R5: =TABLA_BASE[[#This Row],[DEUDA ADUANERA UNIT.]]*TABLA_BASE[[#This Row],[CANTIDAD (unid.)]] -> 303.64499 | S5: =TABLA_BASE[[#This Row],[DEUDA ADUANERA UNIT.]]*'📋 Datos Generales'!$E$19 -> 0.39220811 | T5: =TABLA_BASE[[#This Row],[DEUDA ADUANERA TOTAL]]*'📋 Datos Generales'!$E$19 -> 1129.5594 | U5: =TABLA_BASE[[#This Row],[ADV UNIT. (US$) ⚠️COSTO]]*'📋 Datos Generales'!$E$19 -> 0.093832628 | V5: =TABLA_BASE[[#This Row],[ADV UNIT. (S/.)]]*TABLA_BASE[[#This Row],[CANTIDAD (unid.)]] -> 270.23797 | W5: =TABLA_BASE[[#This Row],[IPM UNIT. (US$) ✅CF]]*'📋 Datos Generales'!$E$19 -> 0.033141466 | X5: =TABLA_BASE[[#This Row],[IPM UNIT. (S/.)]]*TABLA_BASE[[#This Row],[CANTIDAD (unid.)]] -> 95.447422 | Y5: =TABLA_BASE[[#This Row],[IGV UNIT. (US$) ✅CF]]*'📋 Datos Generales'!$E$19 -> 0.26523402 | Z5: =TABLA_BASE[[#This Row],[IGV UNIT. (S/.)]]*TABLA_BASE[[#This Row],[CANTIDAD (unid.)]] -> 763.87397 | AA5: =TABLA_BASE[[#This Row],[PERCEP. UNIT.(US$) ✅CF]]*'📋 Datos Generales'!$E$19 -> 0.068461677 | AB5: =TABLA_BASE[[#This Row],[PERCEP. UNIT.(S/.)]]*TABLA_BASE[[#This Row],[CANTIDAD (unid.)]] -> 197.16963 | AC5: =TABLA_BASE[[#This Row],[ADV UNIT. (US$) ⚠️COSTO]]+TABLA_BASE[[#This Row],[IPM UNIT. (US$) ✅CF]]+TABLA_BASE[[#This Row],[IGV UNIT. (US$) ✅CF]]+TABLA_BASE[[#This Row],[PERCEP. UNIT.(US$) ✅CF]] -> 0.12383596 | AD5: =TABLA_BASE[[#This Row],[TOTAL PAGO SUNAT UNIT.(US$)]]*TABLA_BASE[[#This Row],[CANTIDAD (unid.)]] -> 356.64758 | AE5: =TABLA_BASE[[#This Row],[TOTAL PAGO SUNAT UNIT.(US$)]]*'📋 Datos Generales'!$E$19 -> 0.46066979 | AF5: =TABLA_BASE[[#This Row],[TOTAL TRIB. UNIT.(S/.)]]*TABLA_BASE[[#This Row],[CANTIDAD (unid.)]] -> 1326.729 | AG5: =IF('🧾 Factura Comercial'!G9=0,0,'📦 Gastos Importación'!$E$28*(IF('🧾 Tributos Aduana'!$F$6=0,0,'🧾 Factura Comercial'!I9/'🧾 Tributos Aduana'!$F$6))/'🧾 Factura Comercial'!G9) -> 0.45628625 | AH5: =TABLA_BASE[[#This Row],[GASTOS IMP. UNIT.(US$)]]*TABLA_BASE[[#This Row],[CANTIDAD (unid.)]] -> 1314.1044 | AI5: =TABLA_BASE[[#This Row],[GASTOS IMP. UNIT.(US$)]]*'📋 Datos Generales'!$E$19 -> 1.6973849 | AJ5: =TABLA_BASE[[#This Row],[GASTOS IMP. UNIT.(S/.)]]*TABLA_BASE[[#This Row],[CANTIDAD (unid.)]] -> 4888.4684 | AK5: ='🧮 Costos x Producto'!J9 -> 0.45628625 | AL5: ='🧮 Costos x Producto'!K9 -> 1.6973849 | AM5: =TABLA_BASE[[#This Row],[C/M UNIT. (S/.)]]*TABLA_BASE[[#This Row],[CANTIDAD (unid.)]] -> 4888.4684 | AN5: =IF('🧾 Factura Comercial'!G9=0,0,'🧾 Tributos Aduana'!$F$17*(IF('🧾 Tributos Aduana'!$F$6=0,0,'🧾 Factura Comercial'!I9/'🧾 Tributos Aduana'!$F$6))/'🧾 Factura Comercial'!G9) -> 0.025223825 | AO5: =IF('🧾 Factura Comercial'!G9=0,0,'🏦 Crédito Fiscal'!$C$16*(IF('🧾 Tributos Aduana'!$F$6=0,0,'🧾 Factura Comercial'!I9/'🧾 Tributos Aduana'!$F$6))/'🧾 Factura Comercial'!G9) -> 0.10047892 | AP5: =TABLA_BASE[[#This Row],[CF UNIT. ✅RECUP. (US$)]]*'📋 Datos Generales'!$E$19 -> 0.37378159 | AQ5: =TABLA_BASE[[#This Row],[CF UNIT. ✅RECUP.(S/.)]]*TABLA_BASE[[#This Row],[CANTIDAD (unid.)]] -> 1076.491 | AR5: ='💰 Precio de Venta'!G10 -> 0.4 | AS5: ='💰 Precio de Venta'!H10 -> 2.8289748 | AT5: =TABLA_BASE[[#This Row],[VALOR VTA. UNIT.(S/.)]]*TABLA_BASE[[#This Row],[CANTIDAD (unid.)]] -> 8147.4473 | AU5: ='💰 Precio de Venta'!I10 -> 3.3381902 | AV5: ='💰 Precio de Venta'!J10 -> 1.1315899 | AW5: =TABLA_BASE[[#This Row],[GANANCIA UNIT.(S/.)]]*TABLA_BASE[[#This Row],[CANTIDAD (unid.)]] -> 3258.9789 | AX5: ='💰 Precio de Venta'!K10 -> 394 | AY5: =TABLA_BASE[[#This Row],[GANANCIA UNIT.(S/.)]]*'🧾 Factura Comercial'!G9 -> 3258.9789 | AZ5: =IF(TABLA_BASE[[#This Row],[PRECIO VTA. c/IGV(S/.)]]=0,0,TABLA_BASE[[#This Row],[GANANCIA UNIT.(S/.)]]/TABLA_BASE[[#This Row],[PRECIO VTA. c/IGV(S/.)]]) -> 0.33898305 | BA5: =IF(TABLA_BASE[[#This Row],[C/M UNIT. (S/.)]]=0,0,TABLA_BASE[[#This Row],[GANANCIA UNIT.(S/.)]]/TABLA_BASE[[#This Row],[C/M UNIT. (S/.)]]) -> 0.66666667 | BB5: =IF(TABLA_BASE[[#This Row],[MARGEN %]]>=0.5,"🟢 ALTO",IF(TABLA_BASE[[#This Row],[MARGEN %]]>=0.3,"🟡 MEDIO","🔴 BAJO")) -> 🟡 MEDIO
A6: ='🧾 Factura Comercial'!E10 -> Audífonos In-Ear con Micrófono | B6: ='🧾 Factura Comercial'!F10 -> Unid. | C6: ='🧾 Factura Comercial'!G10 -> 10224 | D6: ='🧾 Factura Comercial'!H10 -> 0.34 | E6: ='🧾 Factura Comercial'!I10 -> 3476.16 | F6: =IF('🧾 Tributos Aduana'!$F$6=0,0,'🧾 Factura Comercial'!I10/'🧾 Tributos Aduana'!$F$6) -> 0.079653026 | G6: ='🧾 Factura Comercial'!H10*'📋 Datos Generales'!$E$19 -> 1.2648 | H6: =TABLA_BASE[[#This Row],[FOB UNIT. (S/.)]]*TABLA_BASE[[#This Row],[CANTIDAD (unid.)]] -> 12931.315 | I6: =IF('🧾 Tributos Aduana'!$F$6=0,0,'🧾 Tributos Aduana'!$F$17*('🧾 Factura Comercial'!H10/'🧾 Tributos Aduana'!$F$6)) -> 0.021440251 | J6: =TABLA_BASE[[#This Row],[ADV UNIT. (US$) ⚠️COSTO]]*TABLA_BASE[[#This Row],[CANTIDAD (unid.)]] -> 219.20513 | K6: =IF('🧾 Tributos Aduana'!$F$6=0,0,'🧾 Tributos Aduana'!$F$18*('🧾 Factura Comercial'!H10/'🧾 Tributos Aduana'!$F$6)) -> 0.0075726468 | L6: =TABLA_BASE[[#This Row],[IPM UNIT. (US$) ✅CF]]*TABLA_BASE[[#This Row],[CANTIDAD (unid.)]] -> 77.422741 | M6: =IF('🧾 Tributos Aduana'!$F$6=0,0,'🧾 Tributos Aduana'!$F$19*('🧾 Factura Comercial'!H10/'🧾 Tributos Aduana'!$F$6)) -> 0.060604547 | N6: =TABLA_BASE[[#This Row],[IGV UNIT. (US$) ✅CF]]*TABLA_BASE[[#This Row],[CANTIDAD (unid.)]] -> 619.62089 | O6: =IF('🧾 Tributos Aduana'!$F$6=0,0,'🧾 Tributos Aduana'!$F$23*('🧾 Factura Comercial'!H10/'🧾 Tributos Aduana'!$F$6)) -> 0.015643125 | P6: =TABLA_BASE[[#This Row],[PERCEP. UNIT.(US$) ✅CF]]*TABLA_BASE[[#This Row],[CANTIDAD (unid.)]] -> 159.93531 | Q6: =TABLA_BASE[[#This Row],[ADV UNIT. (US$) ⚠️COSTO]]+TABLA_BASE[[#This Row],[IPM UNIT. (US$) ✅CF]]+TABLA_BASE[[#This Row],[IGV UNIT. (US$) ✅CF]] -> 0.089617445 | R6: =TABLA_BASE[[#This Row],[DEUDA ADUANERA UNIT.]]*TABLA_BASE[[#This Row],[CANTIDAD (unid.)]] -> 916.24876 | S6: =TABLA_BASE[[#This Row],[DEUDA ADUANERA UNIT.]]*'📋 Datos Generales'!$E$19 -> 0.33337689 | T6: =TABLA_BASE[[#This Row],[DEUDA ADUANERA TOTAL]]*'📋 Datos Generales'!$E$19 -> 3408.4454 | U6: =TABLA_BASE[[#This Row],[ADV UNIT. (US$) ⚠️COSTO]]*'📋 Datos Generales'!$E$19 -> 0.079757734 | V6: =TABLA_BASE[[#This Row],[ADV UNIT. (S/.)]]*TABLA_BASE[[#This Row],[CANTIDAD (unid.)]] -> 815.44307 | W6: =TABLA_BASE[[#This Row],[IPM UNIT. (US$) ✅CF]]*'📋 Datos Generales'!$E$19 -> 0.028170246 | X6: =TABLA_BASE[[#This Row],[IPM UNIT. (S/.)]]*TABLA_BASE[[#This Row],[CANTIDAD (unid.)]] -> 288.0126 | Y6: =TABLA_BASE[[#This Row],[IGV UNIT. (US$) ✅CF]]*'📋 Datos Generales'!$E$19 -> 0.22544891 | Z6: =TABLA_BASE[[#This Row],[IGV UNIT. (S/.)]]*TABLA_BASE[[#This Row],[CANTIDAD (unid.)]] -> 2304.9897 | AA6: =TABLA_BASE[[#This Row],[PERCEP. UNIT.(US$) ✅CF]]*'📋 Datos Generales'!$E$19 -> 0.058192425 | AB6: =TABLA_BASE[[#This Row],[PERCEP. UNIT.(S/.)]]*TABLA_BASE[[#This Row],[CANTIDAD (unid.)]] -> 594.95935 | AC6: =TABLA_BASE[[#This Row],[ADV UNIT. (US$) ⚠️COSTO]]+TABLA_BASE[[#This Row],[IPM UNIT. (US$) ✅CF]]+TABLA_BASE[[#This Row],[IGV UNIT. (US$) ✅CF]]+TABLA_BASE[[#This Row],[PERCEP. UNIT.(US$) ✅CF]] -> 0.10526057 | AD6: =TABLA_BASE[[#This Row],[TOTAL PAGO SUNAT UNIT.(US$)]]*TABLA_BASE[[#This Row],[CANTIDAD (unid.)]] -> 1076.1841 | AE6: =TABLA_BASE[[#This Row],[TOTAL PAGO SUNAT UNIT.(US$)]]*'📋 Datos Generales'!$E$19 -> 0.39156932 | AF6: =TABLA_BASE[[#This Row],[TOTAL TRIB. UNIT.(S/.)]]*TABLA_BASE[[#This Row],[CANTIDAD (unid.)]] -> 4003.4047 | AG6: =IF('🧾 Factura Comercial'!G10=0,0,'📦 Gastos Importación'!$E$28*(IF('🧾 Tributos Aduana'!$F$6=0,0,'🧾 Factura Comercial'!I10/'🧾 Tributos Aduana'!$F$6))/'🧾 Factura Comercial'!G10) -> 0.38784331 | AH6: =TABLA_BASE[[#This Row],[GASTOS IMP. UNIT.(US$)]]*TABLA_BASE[[#This Row],[CANTIDAD (unid.)]] -> 3965.31 | AI6: =TABLA_BASE[[#This Row],[GASTOS IMP. UNIT.(US$)]]*'📋 Datos Generales'!$E$19 -> 1.4427771 | AJ6: =TABLA_BASE[[#This Row],[GASTOS IMP. UNIT.(S/.)]]*TABLA_BASE[[#This Row],[CANTIDAD (unid.)]] -> 14750.953 | AK6: ='🧮 Costos x Producto'!J10 -> 0.38784331 | AL6: ='🧮 Costos x Producto'!K10 -> 1.4427771 | AM6: =TABLA_BASE[[#This Row],[C/M UNIT. (S/.)]]*TABLA_BASE[[#This Row],[CANTIDAD (unid.)]] -> 14750.953 | AN6: =IF('🧾 Factura Comercial'!G10=0,0,'🧾 Tributos Aduana'!$F$17*(IF('🧾 Tributos Aduana'!$F$6=0,0,'🧾 Factura Comercial'!I10/'🧾 Tributos Aduana'!$F$6))/'🧾 Factura Comercial'!G10) -> 0.021440251 | AO6: =IF('🧾 Factura Comercial'!G10=0,0,'🏦 Crédito Fiscal'!$C$16*(IF('🧾 Tributos Aduana'!$F$6=0,0,'🧾 Factura Comercial'!I10/'🧾 Tributos Aduana'!$F$6))/'🧾 Factura Comercial'!G10) -> 0.085407083 | AP6: =TABLA_BASE[[#This Row],[CF UNIT. ✅RECUP. (US$)]]*'📋 Datos Generales'!$E$19 -> 0.31771435 | AQ6: =TABLA_BASE[[#This Row],[CF UNIT. ✅RECUP.(S/.)]]*TABLA_BASE[[#This Row],[CANTIDAD (unid.)]] -> 3248.3115 | AR6: ='💰 Precio de Venta'!G11 -> 0.4 | AS6: ='💰 Precio de Venta'!H11 -> 2.4046285 | AT6: =TABLA_BASE[[#This Row],[VALOR VTA. UNIT.(S/.)]]*TABLA_BASE[[#This Row],[CANTIDAD (unid.)]] -> 24584.922 | AU6: ='💰 Precio de Venta'!I11 -> 2.8374617 | AV6: ='💰 Precio de Venta'!J11 -> 0.96185142 | AW6: =TABLA_BASE[[#This Row],[GANANCIA UNIT.(S/.)]]*TABLA_BASE[[#This Row],[CANTIDAD (unid.)]] -> 9833.9689 | AX6: ='💰 Precio de Venta'!K11 -> 1398 | AY6: =TABLA_BASE[[#This Row],[GANANCIA UNIT.(S/.)]]*'🧾 Factura Comercial'!G10 -> 9833.9689 | AZ6: =IF(TABLA_BASE[[#This Row],[PRECIO VTA. c/IGV(S/.)]]=0,0,TABLA_BASE[[#This Row],[GANANCIA UNIT.(S/.)]]/TABLA_BASE[[#This Row],[PRECIO VTA. c/IGV(S/.)]]) -> 0.33898305 | BA6: =IF(TABLA_BASE[[#This Row],[C/M UNIT. (S/.)]]=0,0,TABLA_BASE[[#This Row],[GANANCIA UNIT.(S/.)]]/TABLA_BASE[[#This Row],[C/M UNIT. (S/.)]]) -> 0.66666667 | BB6: =IF(TABLA_BASE[[#This Row],[MARGEN %]]>=0.5,"🟢 ALTO",IF(TABLA_BASE[[#This Row],[MARGEN %]]>=0.3,"🟡 MEDIO","🔴 BAJO")) -> 🟡 MEDIO
